[2019-12-28 13:23:37] name:分久再合.Splitting.Up.Together.S02E18.720p.HDTV.Classic字幕组.mp4 url:https://91mjw.com/all/page/15 No connection adapters were found for 'ttps://imgcdn.91pic.org/mjw/007bEUxMly1fwejmxhcvyj30zk0k0q4l.jpg'
Traceback (most recent call last):
  File "91.py", line 149, in <module>
    img_file = requests.get(img['data-original']).content
  File "/usr/local/lib/python3.7/site-packages/requests/api.py", line 75, in get
    return request('get', url, params=params, **kwargs)
  File "/usr/local/lib/python3.7/site-packages/requests/api.py", line 60, in request
    return session.request(method=method, url=url, **kwargs)
  File "/usr/local/lib/python3.7/site-packages/requests/sessions.py", line 533, in request
    resp = self.send(prep, **send_kwargs)
  File "/usr/local/lib/python3.7/site-packages/requests/sessions.py", line 640, in send
    adapter = self.get_adapter(url=request.url)
  File "/usr/local/lib/python3.7/site-packages/requests/sessions.py", line 731, in get_adapter
    raise InvalidSchema("No connection adapters were found for '%s'" % url)
requests.exceptions.InvalidSchema: No connection adapters were found for 'ttps://imgcdn.91pic.org/mjw/007bEUxMly1fwejmxhcvyj30zk0k0q4l.jpg'

[2019-12-28 13:27:43] name:发现女巫 url:https://91mjw.com/all/page/17 'NoneType' object has no attribute 'next_sibling'
Traceback (most recent call last):
  File "91.py", line 44, in <module>
    area = area_el.next_sibling
AttributeError: 'NoneType' object has no attribute 'next_sibling'

[2019-12-28 13:28:49] name:碟中谍6：全面瓦解 url:https://91mjw.com/all/page/17 Invalid URL '//img5.mtime.cn/mg/2018/08/27/173222.31618764_270X405X4.jpg': No schema supplied. Perhaps you meant http:////img5.mtime.cn/mg/2018/08/27/173222.31618764_270X405X4.jpg?
Traceback (most recent call last):
  File "91.py", line 100, in <module>
    img_file = requests.get(cover_picture_origin).content
  File "/usr/local/lib/python3.7/site-packages/requests/api.py", line 75, in get
    return request('get', url, params=params, **kwargs)
  File "/usr/local/lib/python3.7/site-packages/requests/api.py", line 60, in request
    return session.request(method=method, url=url, **kwargs)
  File "/usr/local/lib/python3.7/site-packages/requests/sessions.py", line 519, in request
    prep = self.prepare_request(req)
  File "/usr/local/lib/python3.7/site-packages/requests/sessions.py", line 462, in prepare_request
    hooks=merge_hooks(request.hooks, self.hooks),
  File "/usr/local/lib/python3.7/site-packages/requests/models.py", line 313, in prepare
    self.prepare_url(url, params)
  File "/usr/local/lib/python3.7/site-packages/requests/models.py", line 387, in prepare_url
    raise MissingSchema(error)
requests.exceptions.MissingSchema: Invalid URL '//img5.mtime.cn/mg/2018/08/27/173222.31618764_270X405X4.jpg': No schema supplied. Perhaps you meant http:////img5.mtime.cn/mg/2018/08/27/173222.31618764_270X405X4.jpg?

[2019-12-28 13:29:06] name:爱的过去进行式 url:https://91mjw.com/all/page/18 Invalid URL '//img5.mtime.cn/mg/2018/07/27/110628.13327655_270X405X4.jpg': No schema supplied. Perhaps you meant http:////img5.mtime.cn/mg/2018/07/27/110628.13327655_270X405X4.jpg?
Traceback (most recent call last):
  File "91.py", line 100, in <module>
    img_file = requests.get(cover_picture_origin).content
  File "/usr/local/lib/python3.7/site-packages/requests/api.py", line 75, in get
    return request('get', url, params=params, **kwargs)
  File "/usr/local/lib/python3.7/site-packages/requests/api.py", line 60, in request
    return session.request(method=method, url=url, **kwargs)
  File "/usr/local/lib/python3.7/site-packages/requests/sessions.py", line 519, in request
    prep = self.prepare_request(req)
  File "/usr/local/lib/python3.7/site-packages/requests/sessions.py", line 462, in prepare_request
    hooks=merge_hooks(request.hooks, self.hooks),
  File "/usr/local/lib/python3.7/site-packages/requests/models.py", line 313, in prepare
    self.prepare_url(url, params)
  File "/usr/local/lib/python3.7/site-packages/requests/models.py", line 387, in prepare_url
    raise MissingSchema(error)
requests.exceptions.MissingSchema: Invalid URL '//img5.mtime.cn/mg/2018/07/27/110628.13327655_270X405X4.jpg': No schema supplied. Perhaps you meant http:////img5.mtime.cn/mg/2018/07/27/110628.13327655_270X405X4.jpg?

[2019-12-28 13:29:36] name:巨齿鲨 url:https://91mjw.com/all/page/18 Invalid URL '//img5.mtime.cn/mg/2018/08/02/154114.97256141_270X405X4.jpg': No schema supplied. Perhaps you meant http:////img5.mtime.cn/mg/2018/08/02/154114.97256141_270X405X4.jpg?
Traceback (most recent call last):
  File "91.py", line 100, in <module>
    img_file = requests.get(cover_picture_origin).content
  File "/usr/local/lib/python3.7/site-packages/requests/api.py", line 75, in get
    return request('get', url, params=params, **kwargs)
  File "/usr/local/lib/python3.7/site-packages/requests/api.py", line 60, in request
    return session.request(method=method, url=url, **kwargs)
  File "/usr/local/lib/python3.7/site-packages/requests/sessions.py", line 519, in request
    prep = self.prepare_request(req)
  File "/usr/local/lib/python3.7/site-packages/requests/sessions.py", line 462, in prepare_request
    hooks=merge_hooks(request.hooks, self.hooks),
  File "/usr/local/lib/python3.7/site-packages/requests/models.py", line 313, in prepare
    self.prepare_url(url, params)
  File "/usr/local/lib/python3.7/site-packages/requests/models.py", line 387, in prepare_url
    raise MissingSchema(error)
requests.exceptions.MissingSchema: Invalid URL '//img5.mtime.cn/mg/2018/08/02/154114.97256141_270X405X4.jpg': No schema supplied. Perhaps you meant http:////img5.mtime.cn/mg/2018/08/02/154114.97256141_270X405X4.jpg?

[2019-12-28 13:29:51] name:克里斯托弗·罗宾 url:https://91mjw.com/all/page/18 Invalid URL '//img5.mtime.cn/mg/2018/05/25/094224.98692478_270X405X4.jpg': No schema supplied. Perhaps you meant http:////img5.mtime.cn/mg/2018/05/25/094224.98692478_270X405X4.jpg?
Traceback (most recent call last):
  File "91.py", line 100, in <module>
    img_file = requests.get(cover_picture_origin).content
  File "/usr/local/lib/python3.7/site-packages/requests/api.py", line 75, in get
    return request('get', url, params=params, **kwargs)
  File "/usr/local/lib/python3.7/site-packages/requests/api.py", line 60, in request
    return session.request(method=method, url=url, **kwargs)
  File "/usr/local/lib/python3.7/site-packages/requests/sessions.py", line 519, in request
    prep = self.prepare_request(req)
  File "/usr/local/lib/python3.7/site-packages/requests/sessions.py", line 462, in prepare_request
    hooks=merge_hooks(request.hooks, self.hooks),
  File "/usr/local/lib/python3.7/site-packages/requests/models.py", line 313, in prepare
    self.prepare_url(url, params)
  File "/usr/local/lib/python3.7/site-packages/requests/models.py", line 387, in prepare_url
    raise MissingSchema(error)
requests.exceptions.MissingSchema: Invalid URL '//img5.mtime.cn/mg/2018/05/25/094224.98692478_270X405X4.jpg': No schema supplied. Perhaps you meant http:////img5.mtime.cn/mg/2018/05/25/094224.98692478_270X405X4.jpg?

[2019-12-28 13:29:52] name:八年级 url:https://91mjw.com/all/page/18 Invalid URL '//img5.mtime.cn/mg/2018/03/15/103306.26875320_270X405X4.jpg': No schema supplied. Perhaps you meant http:////img5.mtime.cn/mg/2018/03/15/103306.26875320_270X405X4.jpg?
Traceback (most recent call last):
  File "91.py", line 100, in <module>
    img_file = requests.get(cover_picture_origin).content
  File "/usr/local/lib/python3.7/site-packages/requests/api.py", line 75, in get
    return request('get', url, params=params, **kwargs)
  File "/usr/local/lib/python3.7/site-packages/requests/api.py", line 60, in request
    return session.request(method=method, url=url, **kwargs)
  File "/usr/local/lib/python3.7/site-packages/requests/sessions.py", line 519, in request
    prep = self.prepare_request(req)
  File "/usr/local/lib/python3.7/site-packages/requests/sessions.py", line 462, in prepare_request
    hooks=merge_hooks(request.hooks, self.hooks),
  File "/usr/local/lib/python3.7/site-packages/requests/models.py", line 313, in prepare
    self.prepare_url(url, params)
  File "/usr/local/lib/python3.7/site-packages/requests/models.py", line 387, in prepare_url
    raise MissingSchema(error)
requests.exceptions.MissingSchema: Invalid URL '//img5.mtime.cn/mg/2018/03/15/103306.26875320_270X405X4.jpg': No schema supplied. Perhaps you meant http:////img5.mtime.cn/mg/2018/03/15/103306.26875320_270X405X4.jpg?

[2019-12-28 13:29:52] name:我的间谍前男友 url:https://91mjw.com/all/page/18 Invalid URL '//img5.mtime.cn/mg/2018/09/11/174028.72762240_270X405X4.jpg': No schema supplied. Perhaps you meant http:////img5.mtime.cn/mg/2018/09/11/174028.72762240_270X405X4.jpg?
Traceback (most recent call last):
  File "91.py", line 100, in <module>
    img_file = requests.get(cover_picture_origin).content
  File "/usr/local/lib/python3.7/site-packages/requests/api.py", line 75, in get
    return request('get', url, params=params, **kwargs)
  File "/usr/local/lib/python3.7/site-packages/requests/api.py", line 60, in request
    return session.request(method=method, url=url, **kwargs)
  File "/usr/local/lib/python3.7/site-packages/requests/sessions.py", line 519, in request
    prep = self.prepare_request(req)
  File "/usr/local/lib/python3.7/site-packages/requests/sessions.py", line 462, in prepare_request
    hooks=merge_hooks(request.hooks, self.hooks),
  File "/usr/local/lib/python3.7/site-packages/requests/models.py", line 313, in prepare
    self.prepare_url(url, params)
  File "/usr/local/lib/python3.7/site-packages/requests/models.py", line 387, in prepare_url
    raise MissingSchema(error)
requests.exceptions.MissingSchema: Invalid URL '//img5.mtime.cn/mg/2018/09/11/174028.72762240_270X405X4.jpg': No schema supplied. Perhaps you meant http:////img5.mtime.cn/mg/2018/09/11/174028.72762240_270X405X4.jpg?

[2019-12-28 13:30:05] name:伸冤人2 url:https://91mjw.com/all/page/18 Invalid URL '//img5.mtime.cn/pi/2018/09/13/104058.61653983_270X405.jpg': No schema supplied. Perhaps you meant http:////img5.mtime.cn/pi/2018/09/13/104058.61653983_270X405.jpg?
Traceback (most recent call last):
  File "91.py", line 100, in <module>
    img_file = requests.get(cover_picture_origin).content
  File "/usr/local/lib/python3.7/site-packages/requests/api.py", line 75, in get
    return request('get', url, params=params, **kwargs)
  File "/usr/local/lib/python3.7/site-packages/requests/api.py", line 60, in request
    return session.request(method=method, url=url, **kwargs)
  File "/usr/local/lib/python3.7/site-packages/requests/sessions.py", line 519, in request
    prep = self.prepare_request(req)
  File "/usr/local/lib/python3.7/site-packages/requests/sessions.py", line 462, in prepare_request
    hooks=merge_hooks(request.hooks, self.hooks),
  File "/usr/local/lib/python3.7/site-packages/requests/models.py", line 313, in prepare
    self.prepare_url(url, params)
  File "/usr/local/lib/python3.7/site-packages/requests/models.py", line 387, in prepare_url
    raise MissingSchema(error)
requests.exceptions.MissingSchema: Invalid URL '//img5.mtime.cn/pi/2018/09/13/104058.61653983_270X405.jpg': No schema supplied. Perhaps you meant http:////img5.mtime.cn/pi/2018/09/13/104058.61653983_270X405.jpg?

[2019-12-28 13:30:18] name:摩天营救 url:https://91mjw.com/all/page/18 Invalid URL '//img5.mtime.cn/mg/2018/07/11/151452.54932020_270X405X4.jpg': No schema supplied. Perhaps you meant http:////img5.mtime.cn/mg/2018/07/11/151452.54932020_270X405X4.jpg?
Traceback (most recent call last):
  File "91.py", line 100, in <module>
    img_file = requests.get(cover_picture_origin).content
  File "/usr/local/lib/python3.7/site-packages/requests/api.py", line 75, in get
    return request('get', url, params=params, **kwargs)
  File "/usr/local/lib/python3.7/site-packages/requests/api.py", line 60, in request
    return session.request(method=method, url=url, **kwargs)
  File "/usr/local/lib/python3.7/site-packages/requests/sessions.py", line 519, in request
    prep = self.prepare_request(req)
  File "/usr/local/lib/python3.7/site-packages/requests/sessions.py", line 462, in prepare_request
    hooks=merge_hooks(request.hooks, self.hooks),
  File "/usr/local/lib/python3.7/site-packages/requests/models.py", line 313, in prepare
    self.prepare_url(url, params)
  File "/usr/local/lib/python3.7/site-packages/requests/models.py", line 387, in prepare_url
    raise MissingSchema(error)
requests.exceptions.MissingSchema: Invalid URL '//img5.mtime.cn/mg/2018/07/11/151452.54932020_270X405X4.jpg': No schema supplied. Perhaps you meant http:////img5.mtime.cn/mg/2018/07/11/151452.54932020_270X405X4.jpg?

[2019-12-28 13:30:19] name:解除好友2：暗网 url:https://91mjw.com/all/page/18 Invalid URL '//img5.mtime.cn/mt/2018/06/15/110216.62112755_270X405.jpg': No schema supplied. Perhaps you meant http:////img5.mtime.cn/mt/2018/06/15/110216.62112755_270X405.jpg?
Traceback (most recent call last):
  File "91.py", line 100, in <module>
    img_file = requests.get(cover_picture_origin).content
  File "/usr/local/lib/python3.7/site-packages/requests/api.py", line 75, in get
    return request('get', url, params=params, **kwargs)
  File "/usr/local/lib/python3.7/site-packages/requests/api.py", line 60, in request
    return session.request(method=method, url=url, **kwargs)
  File "/usr/local/lib/python3.7/site-packages/requests/sessions.py", line 519, in request
    prep = self.prepare_request(req)
  File "/usr/local/lib/python3.7/site-packages/requests/sessions.py", line 462, in prepare_request
    hooks=merge_hooks(request.hooks, self.hooks),
  File "/usr/local/lib/python3.7/site-packages/requests/models.py", line 313, in prepare
    self.prepare_url(url, params)
  File "/usr/local/lib/python3.7/site-packages/requests/models.py", line 387, in prepare_url
    raise MissingSchema(error)
requests.exceptions.MissingSchema: Invalid URL '//img5.mtime.cn/mt/2018/06/15/110216.62112755_270X405.jpg': No schema supplied. Perhaps you meant http:////img5.mtime.cn/mt/2018/06/15/110216.62112755_270X405.jpg?

[2019-12-28 13:30:19] name:妈妈咪呀2 url:https://91mjw.com/all/page/18 Invalid URL '//img5.mtime.cn/mg/2018/07/18/093137.11437875_270X405X4.jpg': No schema supplied. Perhaps you meant http:////img5.mtime.cn/mg/2018/07/18/093137.11437875_270X405X4.jpg?
Traceback (most recent call last):
  File "91.py", line 100, in <module>
    img_file = requests.get(cover_picture_origin).content
  File "/usr/local/lib/python3.7/site-packages/requests/api.py", line 75, in get
    return request('get', url, params=params, **kwargs)
  File "/usr/local/lib/python3.7/site-packages/requests/api.py", line 60, in request
    return session.request(method=method, url=url, **kwargs)
  File "/usr/local/lib/python3.7/site-packages/requests/sessions.py", line 519, in request
    prep = self.prepare_request(req)
  File "/usr/local/lib/python3.7/site-packages/requests/sessions.py", line 462, in prepare_request
    hooks=merge_hooks(request.hooks, self.hooks),
  File "/usr/local/lib/python3.7/site-packages/requests/models.py", line 313, in prepare
    self.prepare_url(url, params)
  File "/usr/local/lib/python3.7/site-packages/requests/models.py", line 387, in prepare_url
    raise MissingSchema(error)
requests.exceptions.MissingSchema: Invalid URL '//img5.mtime.cn/mg/2018/07/18/093137.11437875_270X405X4.jpg': No schema supplied. Perhaps you meant http:////img5.mtime.cn/mg/2018/07/18/093137.11437875_270X405X4.jpg?

[2019-12-28 13:30:35] name:精灵旅社3 url:https://91mjw.com/all/page/19 Invalid URL '//img5.mtime.cn/mg/2018/08/10/143744.47525207_270X405X4.jpg': No schema supplied. Perhaps you meant http:////img5.mtime.cn/mg/2018/08/10/143744.47525207_270X405X4.jpg?
Traceback (most recent call last):
  File "91.py", line 100, in <module>
    img_file = requests.get(cover_picture_origin).content
  File "/usr/local/lib/python3.7/site-packages/requests/api.py", line 75, in get
    return request('get', url, params=params, **kwargs)
  File "/usr/local/lib/python3.7/site-packages/requests/api.py", line 60, in request
    return session.request(method=method, url=url, **kwargs)
  File "/usr/local/lib/python3.7/site-packages/requests/sessions.py", line 519, in request
    prep = self.prepare_request(req)
  File "/usr/local/lib/python3.7/site-packages/requests/sessions.py", line 462, in prepare_request
    hooks=merge_hooks(request.hooks, self.hooks),
  File "/usr/local/lib/python3.7/site-packages/requests/models.py", line 313, in prepare
    self.prepare_url(url, params)
  File "/usr/local/lib/python3.7/site-packages/requests/models.py", line 387, in prepare_url
    raise MissingSchema(error)
requests.exceptions.MissingSchema: Invalid URL '//img5.mtime.cn/mg/2018/08/10/143744.47525207_270X405X4.jpg': No schema supplied. Perhaps you meant http:////img5.mtime.cn/mg/2018/08/10/143744.47525207_270X405X4.jpg?

[2019-12-28 13:30:42] name:蚁人2：黄蜂女现身 url:https://91mjw.com/all/page/19 Invalid URL '//img5.mtime.cn/mg/2018/08/01/102502.35736373_270X405X4.jpg': No schema supplied. Perhaps you meant http:////img5.mtime.cn/mg/2018/08/01/102502.35736373_270X405X4.jpg?
Traceback (most recent call last):
  File "91.py", line 100, in <module>
    img_file = requests.get(cover_picture_origin).content
  File "/usr/local/lib/python3.7/site-packages/requests/api.py", line 75, in get
    return request('get', url, params=params, **kwargs)
  File "/usr/local/lib/python3.7/site-packages/requests/api.py", line 60, in request
    return session.request(method=method, url=url, **kwargs)
  File "/usr/local/lib/python3.7/site-packages/requests/sessions.py", line 519, in request
    prep = self.prepare_request(req)
  File "/usr/local/lib/python3.7/site-packages/requests/sessions.py", line 462, in prepare_request
    hooks=merge_hooks(request.hooks, self.hooks),
  File "/usr/local/lib/python3.7/site-packages/requests/models.py", line 313, in prepare
    self.prepare_url(url, params)
  File "/usr/local/lib/python3.7/site-packages/requests/models.py", line 387, in prepare_url
    raise MissingSchema(error)
requests.exceptions.MissingSchema: Invalid URL '//img5.mtime.cn/mg/2018/08/01/102502.35736373_270X405X4.jpg': No schema supplied. Perhaps you meant http:////img5.mtime.cn/mg/2018/08/01/102502.35736373_270X405X4.jpg?

[2019-12-28 13:30:46] name:人类清除计划4 url:https://91mjw.com/all/page/19 Invalid URL '//img5.mtime.cn/mg/2018/06/25/144547.98043398_270X405X4.jpg': No schema supplied. Perhaps you meant http:////img5.mtime.cn/mg/2018/06/25/144547.98043398_270X405X4.jpg?
Traceback (most recent call last):
  File "91.py", line 100, in <module>
    img_file = requests.get(cover_picture_origin).content
  File "/usr/local/lib/python3.7/site-packages/requests/api.py", line 75, in get
    return request('get', url, params=params, **kwargs)
  File "/usr/local/lib/python3.7/site-packages/requests/api.py", line 60, in request
    return session.request(method=method, url=url, **kwargs)
  File "/usr/local/lib/python3.7/site-packages/requests/sessions.py", line 519, in request
    prep = self.prepare_request(req)
  File "/usr/local/lib/python3.7/site-packages/requests/sessions.py", line 462, in prepare_request
    hooks=merge_hooks(request.hooks, self.hooks),
  File "/usr/local/lib/python3.7/site-packages/requests/models.py", line 313, in prepare
    self.prepare_url(url, params)
  File "/usr/local/lib/python3.7/site-packages/requests/models.py", line 387, in prepare_url
    raise MissingSchema(error)
requests.exceptions.MissingSchema: Invalid URL '//img5.mtime.cn/mg/2018/06/25/144547.98043398_270X405X4.jpg': No schema supplied. Perhaps you meant http:////img5.mtime.cn/mg/2018/06/25/144547.98043398_270X405X4.jpg?

[2019-12-28 13:30:56] name:边境杀手2 url:https://91mjw.com/all/page/19 Invalid URL '//img5.mtime.cn/mg/2018/05/07/162847.91768594_270X405X4.jpg': No schema supplied. Perhaps you meant http:////img5.mtime.cn/mg/2018/05/07/162847.91768594_270X405X4.jpg?
Traceback (most recent call last):
  File "91.py", line 100, in <module>
    img_file = requests.get(cover_picture_origin).content
  File "/usr/local/lib/python3.7/site-packages/requests/api.py", line 75, in get
    return request('get', url, params=params, **kwargs)
  File "/usr/local/lib/python3.7/site-packages/requests/api.py", line 60, in request
    return session.request(method=method, url=url, **kwargs)
  File "/usr/local/lib/python3.7/site-packages/requests/sessions.py", line 519, in request
    prep = self.prepare_request(req)
  File "/usr/local/lib/python3.7/site-packages/requests/sessions.py", line 462, in prepare_request
    hooks=merge_hooks(request.hooks, self.hooks),
  File "/usr/local/lib/python3.7/site-packages/requests/models.py", line 313, in prepare
    self.prepare_url(url, params)
  File "/usr/local/lib/python3.7/site-packages/requests/models.py", line 387, in prepare_url
    raise MissingSchema(error)
requests.exceptions.MissingSchema: Invalid URL '//img5.mtime.cn/mg/2018/05/07/162847.91768594_270X405X4.jpg': No schema supplied. Perhaps you meant http:////img5.mtime.cn/mg/2018/05/07/162847.91768594_270X405X4.jpg?

[2019-12-28 13:31:18] name:生死狙击 url:https://91mjw.com/all/page/19 'NoneType' object is not subscriptable
Traceback (most recent call last):
  File "91.py", line 117, in <module>
    title, name, str(director), str(scriptwriter), str(cast), category, cat_id[0],
TypeError: 'NoneType' object is not subscriptable

[2019-12-28 13:31:47] name:超人总动员2 url:https://91mjw.com/all/page/19 Invalid URL '//img5.mtime.cn/mg/2018/05/23/125015.71508361_270X405X4.jpg': No schema supplied. Perhaps you meant http:////img5.mtime.cn/mg/2018/05/23/125015.71508361_270X405X4.jpg?
Traceback (most recent call last):
  File "91.py", line 100, in <module>
    img_file = requests.get(cover_picture_origin).content
  File "/usr/local/lib/python3.7/site-packages/requests/api.py", line 75, in get
    return request('get', url, params=params, **kwargs)
  File "/usr/local/lib/python3.7/site-packages/requests/api.py", line 60, in request
    return session.request(method=method, url=url, **kwargs)
  File "/usr/local/lib/python3.7/site-packages/requests/sessions.py", line 519, in request
    prep = self.prepare_request(req)
  File "/usr/local/lib/python3.7/site-packages/requests/sessions.py", line 462, in prepare_request
    hooks=merge_hooks(request.hooks, self.hooks),
  File "/usr/local/lib/python3.7/site-packages/requests/models.py", line 313, in prepare
    self.prepare_url(url, params)
  File "/usr/local/lib/python3.7/site-packages/requests/models.py", line 387, in prepare_url
    raise MissingSchema(error)
requests.exceptions.MissingSchema: Invalid URL '//img5.mtime.cn/mg/2018/05/23/125015.71508361_270X405X4.jpg': No schema supplied. Perhaps you meant http:////img5.mtime.cn/mg/2018/05/23/125015.71508361_270X405X4.jpg?

[2019-12-28 13:31:48] name:侏罗纪世界2 url:https://91mjw.com/all/page/19 Invalid URL '//img5.mtime.cn/mg/2018/05/25/100001.46893840_270X405X4.jpg': No schema supplied. Perhaps you meant http:////img5.mtime.cn/mg/2018/05/25/100001.46893840_270X405X4.jpg?
Traceback (most recent call last):
  File "91.py", line 100, in <module>
    img_file = requests.get(cover_picture_origin).content
  File "/usr/local/lib/python3.7/site-packages/requests/api.py", line 75, in get
    return request('get', url, params=params, **kwargs)
  File "/usr/local/lib/python3.7/site-packages/requests/api.py", line 60, in request
    return session.request(method=method, url=url, **kwargs)
  File "/usr/local/lib/python3.7/site-packages/requests/sessions.py", line 519, in request
    prep = self.prepare_request(req)
  File "/usr/local/lib/python3.7/site-packages/requests/sessions.py", line 462, in prepare_request
    hooks=merge_hooks(request.hooks, self.hooks),
  File "/usr/local/lib/python3.7/site-packages/requests/models.py", line 313, in prepare
    self.prepare_url(url, params)
  File "/usr/local/lib/python3.7/site-packages/requests/models.py", line 387, in prepare_url
    raise MissingSchema(error)
requests.exceptions.MissingSchema: Invalid URL '//img5.mtime.cn/mg/2018/05/25/100001.46893840_270X405X4.jpg': No schema supplied. Perhaps you meant http:////img5.mtime.cn/mg/2018/05/25/100001.46893840_270X405X4.jpg?

[2019-12-28 13:32:36] name:升级 url:https://91mjw.com/all/page/20 Invalid URL '//img5.mtime.cn/mg/2018/04/04/173453.39147690_270X405X4.jpg': No schema supplied. Perhaps you meant http:////img5.mtime.cn/mg/2018/04/04/173453.39147690_270X405X4.jpg?
Traceback (most recent call last):
  File "91.py", line 100, in <module>
    img_file = requests.get(cover_picture_origin).content
  File "/usr/local/lib/python3.7/site-packages/requests/api.py", line 75, in get
    return request('get', url, params=params, **kwargs)
  File "/usr/local/lib/python3.7/site-packages/requests/api.py", line 60, in request
    return session.request(method=method, url=url, **kwargs)
  File "/usr/local/lib/python3.7/site-packages/requests/sessions.py", line 519, in request
    prep = self.prepare_request(req)
  File "/usr/local/lib/python3.7/site-packages/requests/sessions.py", line 462, in prepare_request
    hooks=merge_hooks(request.hooks, self.hooks),
  File "/usr/local/lib/python3.7/site-packages/requests/models.py", line 313, in prepare
    self.prepare_url(url, params)
  File "/usr/local/lib/python3.7/site-packages/requests/models.py", line 387, in prepare_url
    raise MissingSchema(error)
requests.exceptions.MissingSchema: Invalid URL '//img5.mtime.cn/mg/2018/04/04/173453.39147690_270X405X4.jpg': No schema supplied. Perhaps you meant http:////img5.mtime.cn/mg/2018/04/04/173453.39147690_270X405X4.jpg?

[2019-12-28 13:32:51] name:信笺故事 url:https://91mjw.com/all/page/20 Invalid URL '//img5.mtime.cn/mg/2018/01/30/111833.63204372_270X405X4.jpg': No schema supplied. Perhaps you meant http:////img5.mtime.cn/mg/2018/01/30/111833.63204372_270X405X4.jpg?
Traceback (most recent call last):
  File "91.py", line 100, in <module>
    img_file = requests.get(cover_picture_origin).content
  File "/usr/local/lib/python3.7/site-packages/requests/api.py", line 75, in get
    return request('get', url, params=params, **kwargs)
  File "/usr/local/lib/python3.7/site-packages/requests/api.py", line 60, in request
    return session.request(method=method, url=url, **kwargs)
  File "/usr/local/lib/python3.7/site-packages/requests/sessions.py", line 519, in request
    prep = self.prepare_request(req)
  File "/usr/local/lib/python3.7/site-packages/requests/sessions.py", line 462, in prepare_request
    hooks=merge_hooks(request.hooks, self.hooks),
  File "/usr/local/lib/python3.7/site-packages/requests/models.py", line 313, in prepare
    self.prepare_url(url, params)
  File "/usr/local/lib/python3.7/site-packages/requests/models.py", line 387, in prepare_url
    raise MissingSchema(error)
requests.exceptions.MissingSchema: Invalid URL '//img5.mtime.cn/mg/2018/01/30/111833.63204372_270X405X4.jpg': No schema supplied. Perhaps you meant http:////img5.mtime.cn/mg/2018/01/30/111833.63204372_270X405X4.jpg?

[2019-12-28 13:32:52] name:游侠索罗 url:https://91mjw.com/all/page/20 Invalid URL '//img5.mtime.cn/mg/2018/05/04/182348.20558908_270X405X4.jpg': No schema supplied. Perhaps you meant http:////img5.mtime.cn/mg/2018/05/04/182348.20558908_270X405X4.jpg?
Traceback (most recent call last):
  File "91.py", line 100, in <module>
    img_file = requests.get(cover_picture_origin).content
  File "/usr/local/lib/python3.7/site-packages/requests/api.py", line 75, in get
    return request('get', url, params=params, **kwargs)
  File "/usr/local/lib/python3.7/site-packages/requests/api.py", line 60, in request
    return session.request(method=method, url=url, **kwargs)
  File "/usr/local/lib/python3.7/site-packages/requests/sessions.py", line 519, in request
    prep = self.prepare_request(req)
  File "/usr/local/lib/python3.7/site-packages/requests/sessions.py", line 462, in prepare_request
    hooks=merge_hooks(request.hooks, self.hooks),
  File "/usr/local/lib/python3.7/site-packages/requests/models.py", line 313, in prepare
    self.prepare_url(url, params)
  File "/usr/local/lib/python3.7/site-packages/requests/models.py", line 387, in prepare_url
    raise MissingSchema(error)
requests.exceptions.MissingSchema: Invalid URL '//img5.mtime.cn/mg/2018/05/04/182348.20558908_270X405X4.jpg': No schema supplied. Perhaps you meant http:////img5.mtime.cn/mg/2018/05/04/182348.20558908_270X405X4.jpg?

[2019-12-28 13:33:00] name:死侍2 url:https://91mjw.com/all/page/20 Invalid URL '//img5.mtime.cn/mg/2018/05/08/093301.23189887_270X405X4.jpg': No schema supplied. Perhaps you meant http:////img5.mtime.cn/mg/2018/05/08/093301.23189887_270X405X4.jpg?
Traceback (most recent call last):
  File "91.py", line 100, in <module>
    img_file = requests.get(cover_picture_origin).content
  File "/usr/local/lib/python3.7/site-packages/requests/api.py", line 75, in get
    return request('get', url, params=params, **kwargs)
  File "/usr/local/lib/python3.7/site-packages/requests/api.py", line 60, in request
    return session.request(method=method, url=url, **kwargs)
  File "/usr/local/lib/python3.7/site-packages/requests/sessions.py", line 519, in request
    prep = self.prepare_request(req)
  File "/usr/local/lib/python3.7/site-packages/requests/sessions.py", line 462, in prepare_request
    hooks=merge_hooks(request.hooks, self.hooks),
  File "/usr/local/lib/python3.7/site-packages/requests/models.py", line 313, in prepare
    self.prepare_url(url, params)
  File "/usr/local/lib/python3.7/site-packages/requests/models.py", line 387, in prepare_url
    raise MissingSchema(error)
requests.exceptions.MissingSchema: Invalid URL '//img5.mtime.cn/mg/2018/05/08/093301.23189887_270X405X4.jpg': No schema supplied. Perhaps you meant http:////img5.mtime.cn/mg/2018/05/08/093301.23189887_270X405X4.jpg?

[2019-12-28 13:33:06] name:复仇者联盟3 url:https://91mjw.com/all/page/20 Invalid URL '//img5.mtime.cn/mg/2018/03/30/101318.97845092_270X405X4.jpg': No schema supplied. Perhaps you meant http:////img5.mtime.cn/mg/2018/03/30/101318.97845092_270X405X4.jpg?
Traceback (most recent call last):
  File "91.py", line 100, in <module>
    img_file = requests.get(cover_picture_origin).content
  File "/usr/local/lib/python3.7/site-packages/requests/api.py", line 75, in get
    return request('get', url, params=params, **kwargs)
  File "/usr/local/lib/python3.7/site-packages/requests/api.py", line 60, in request
    return session.request(method=method, url=url, **kwargs)
  File "/usr/local/lib/python3.7/site-packages/requests/sessions.py", line 519, in request
    prep = self.prepare_request(req)
  File "/usr/local/lib/python3.7/site-packages/requests/sessions.py", line 462, in prepare_request
    hooks=merge_hooks(request.hooks, self.hooks),
  File "/usr/local/lib/python3.7/site-packages/requests/models.py", line 313, in prepare
    self.prepare_url(url, params)
  File "/usr/local/lib/python3.7/site-packages/requests/models.py", line 387, in prepare_url
    raise MissingSchema(error)
requests.exceptions.MissingSchema: Invalid URL '//img5.mtime.cn/mg/2018/03/30/101318.97845092_270X405X4.jpg': No schema supplied. Perhaps you meant http:////img5.mtime.cn/mg/2018/03/30/101318.97845092_270X405X4.jpg?

[2019-12-28 13:35:11] name:环太平洋：雷霆再起 url:https://91mjw.com/all/page/21 Invalid URL '//img5.mtime.cn/mg/2018/02/08/093356.37260679_270X405X4.jpg': No schema supplied. Perhaps you meant http:////img5.mtime.cn/mg/2018/02/08/093356.37260679_270X405X4.jpg?
Traceback (most recent call last):
  File "91.py", line 100, in <module>
    img_file = requests.get(cover_picture_origin).content
  File "/usr/local/lib/python3.7/site-packages/requests/api.py", line 75, in get
    return request('get', url, params=params, **kwargs)
  File "/usr/local/lib/python3.7/site-packages/requests/api.py", line 60, in request
    return session.request(method=method, url=url, **kwargs)
  File "/usr/local/lib/python3.7/site-packages/requests/sessions.py", line 519, in request
    prep = self.prepare_request(req)
  File "/usr/local/lib/python3.7/site-packages/requests/sessions.py", line 462, in prepare_request
    hooks=merge_hooks(request.hooks, self.hooks),
  File "/usr/local/lib/python3.7/site-packages/requests/models.py", line 313, in prepare
    self.prepare_url(url, params)
  File "/usr/local/lib/python3.7/site-packages/requests/models.py", line 387, in prepare_url
    raise MissingSchema(error)
requests.exceptions.MissingSchema: Invalid URL '//img5.mtime.cn/mg/2018/02/08/093356.37260679_270X405X4.jpg': No schema supplied. Perhaps you meant http:////img5.mtime.cn/mg/2018/02/08/093356.37260679_270X405X4.jpg?

[2019-12-28 13:36:12] name:猛龙怪客 url:https://91mjw.com/all/page/22 Invalid URL '//img5.mtime.cn/mg/2018/04/08/150131.65151756_270X405X4.jpg': No schema supplied. Perhaps you meant http:////img5.mtime.cn/mg/2018/04/08/150131.65151756_270X405X4.jpg?
Traceback (most recent call last):
  File "91.py", line 100, in <module>
    img_file = requests.get(cover_picture_origin).content
  File "/usr/local/lib/python3.7/site-packages/requests/api.py", line 75, in get
    return request('get', url, params=params, **kwargs)
  File "/usr/local/lib/python3.7/site-packages/requests/api.py", line 60, in request
    return session.request(method=method, url=url, **kwargs)
  File "/usr/local/lib/python3.7/site-packages/requests/sessions.py", line 519, in request
    prep = self.prepare_request(req)
  File "/usr/local/lib/python3.7/site-packages/requests/sessions.py", line 462, in prepare_request
    hooks=merge_hooks(request.hooks, self.hooks),
  File "/usr/local/lib/python3.7/site-packages/requests/models.py", line 313, in prepare
    self.prepare_url(url, params)
  File "/usr/local/lib/python3.7/site-packages/requests/models.py", line 387, in prepare_url
    raise MissingSchema(error)
requests.exceptions.MissingSchema: Invalid URL '//img5.mtime.cn/mg/2018/04/08/150131.65151756_270X405X4.jpg': No schema supplied. Perhaps you meant http:////img5.mtime.cn/mg/2018/04/08/150131.65151756_270X405X4.jpg?

[2019-12-28 13:38:49] name:幻想快乐 url:https://91mjw.com/all/page/23 Invalid URL '//img5.mtime.cn/mg/2018/01/22/162048.24222202_270X405X4.jpg': No schema supplied. Perhaps you meant http:////img5.mtime.cn/mg/2018/01/22/162048.24222202_270X405X4.jpg?
Traceback (most recent call last):
  File "91.py", line 100, in <module>
    img_file = requests.get(cover_picture_origin).content
  File "/usr/local/lib/python3.7/site-packages/requests/api.py", line 75, in get
    return request('get', url, params=params, **kwargs)
  File "/usr/local/lib/python3.7/site-packages/requests/api.py", line 60, in request
    return session.request(method=method, url=url, **kwargs)
  File "/usr/local/lib/python3.7/site-packages/requests/sessions.py", line 519, in request
    prep = self.prepare_request(req)
  File "/usr/local/lib/python3.7/site-packages/requests/sessions.py", line 462, in prepare_request
    hooks=merge_hooks(request.hooks, self.hooks),
  File "/usr/local/lib/python3.7/site-packages/requests/models.py", line 313, in prepare
    self.prepare_url(url, params)
  File "/usr/local/lib/python3.7/site-packages/requests/models.py", line 387, in prepare_url
    raise MissingSchema(error)
requests.exceptions.MissingSchema: Invalid URL '//img5.mtime.cn/mg/2018/01/22/162048.24222202_270X405X4.jpg': No schema supplied. Perhaps you meant http:////img5.mtime.cn/mg/2018/01/22/162048.24222202_270X405X4.jpg?

[2019-12-28 13:45:45] name:猎杀星期一 url:https://91mjw.com/all/page/26 Invalid URL '//img5.mtime.cn/mg/2017/06/06/154531.61447840_270X405X4.jpg': No schema supplied. Perhaps you meant http:////img5.mtime.cn/mg/2017/06/06/154531.61447840_270X405X4.jpg?
Traceback (most recent call last):
  File "91.py", line 100, in <module>
    img_file = requests.get(cover_picture_origin).content
  File "/usr/local/lib/python3.7/site-packages/requests/api.py", line 75, in get
    return request('get', url, params=params, **kwargs)
  File "/usr/local/lib/python3.7/site-packages/requests/api.py", line 60, in request
    return session.request(method=method, url=url, **kwargs)
  File "/usr/local/lib/python3.7/site-packages/requests/sessions.py", line 519, in request
    prep = self.prepare_request(req)
  File "/usr/local/lib/python3.7/site-packages/requests/sessions.py", line 462, in prepare_request
    hooks=merge_hooks(request.hooks, self.hooks),
  File "/usr/local/lib/python3.7/site-packages/requests/models.py", line 313, in prepare
    self.prepare_url(url, params)
  File "/usr/local/lib/python3.7/site-packages/requests/models.py", line 387, in prepare_url
    raise MissingSchema(error)
requests.exceptions.MissingSchema: Invalid URL '//img5.mtime.cn/mg/2017/06/06/154531.61447840_270X405X4.jpg': No schema supplied. Perhaps you meant http:////img5.mtime.cn/mg/2017/06/06/154531.61447840_270X405X4.jpg?

[2019-12-28 13:48:59] name:银河护卫队2 url:https://91mjw.com/all/page/28 Invalid URL '//img5.mtime.cn/mg/2017/04/01/164330.58769049_270X405X4.jpg': No schema supplied. Perhaps you meant http:////img5.mtime.cn/mg/2017/04/01/164330.58769049_270X405X4.jpg?
Traceback (most recent call last):
  File "91.py", line 100, in <module>
    img_file = requests.get(cover_picture_origin).content
  File "/usr/local/lib/python3.7/site-packages/requests/api.py", line 75, in get
    return request('get', url, params=params, **kwargs)
  File "/usr/local/lib/python3.7/site-packages/requests/api.py", line 60, in request
    return session.request(method=method, url=url, **kwargs)
  File "/usr/local/lib/python3.7/site-packages/requests/sessions.py", line 519, in request
    prep = self.prepare_request(req)
  File "/usr/local/lib/python3.7/site-packages/requests/sessions.py", line 462, in prepare_request
    hooks=merge_hooks(request.hooks, self.hooks),
  File "/usr/local/lib/python3.7/site-packages/requests/models.py", line 313, in prepare
    self.prepare_url(url, params)
  File "/usr/local/lib/python3.7/site-packages/requests/models.py", line 387, in prepare_url
    raise MissingSchema(error)
requests.exceptions.MissingSchema: Invalid URL '//img5.mtime.cn/mg/2017/04/01/164330.58769049_270X405X4.jpg': No schema supplied. Perhaps you meant http:////img5.mtime.cn/mg/2017/04/01/164330.58769049_270X405X4.jpg?

[2019-12-28 13:49:07] name:侍女的故事.The.Handmaids.Tale.S01E10.End.中英字幕.WEB-HR.AAC.720P.x264-人人影视.V2.mp4 url:https://91mjw.com/all/page/28 Invalid URL '//img5.mtime.cn/pi/2016/12/18/161032.42020353_1000X1000.jpg': No schema supplied. Perhaps you meant http:////img5.mtime.cn/pi/2016/12/18/161032.42020353_1000X1000.jpg?
Traceback (most recent call last):
  File "91.py", line 149, in <module>
    img_file = requests.get(img['data-original']).content
  File "/usr/local/lib/python3.7/site-packages/requests/api.py", line 75, in get
    return request('get', url, params=params, **kwargs)
  File "/usr/local/lib/python3.7/site-packages/requests/api.py", line 60, in request
    return session.request(method=method, url=url, **kwargs)
  File "/usr/local/lib/python3.7/site-packages/requests/sessions.py", line 519, in request
    prep = self.prepare_request(req)
  File "/usr/local/lib/python3.7/site-packages/requests/sessions.py", line 462, in prepare_request
    hooks=merge_hooks(request.hooks, self.hooks),
  File "/usr/local/lib/python3.7/site-packages/requests/models.py", line 313, in prepare
    self.prepare_url(url, params)
  File "/usr/local/lib/python3.7/site-packages/requests/models.py", line 387, in prepare_url
    raise MissingSchema(error)
requests.exceptions.MissingSchema: Invalid URL '//img5.mtime.cn/pi/2016/12/18/161032.42020353_1000X1000.jpg': No schema supplied. Perhaps you meant http:////img5.mtime.cn/pi/2016/12/18/161032.42020353_1000X1000.jpg?

[2019-12-28 13:49:08] name:天才 url:https://91mjw.com/all/page/28 Invalid URL '//img5.mtime.cn/mg/2017/04/06/151753.33911673_270X405X4.jpg': No schema supplied. Perhaps you meant http:////img5.mtime.cn/mg/2017/04/06/151753.33911673_270X405X4.jpg?
Traceback (most recent call last):
  File "91.py", line 100, in <module>
    img_file = requests.get(cover_picture_origin).content
  File "/usr/local/lib/python3.7/site-packages/requests/api.py", line 75, in get
    return request('get', url, params=params, **kwargs)
  File "/usr/local/lib/python3.7/site-packages/requests/api.py", line 60, in request
    return session.request(method=method, url=url, **kwargs)
  File "/usr/local/lib/python3.7/site-packages/requests/sessions.py", line 519, in request
    prep = self.prepare_request(req)
  File "/usr/local/lib/python3.7/site-packages/requests/sessions.py", line 462, in prepare_request
    hooks=merge_hooks(request.hooks, self.hooks),
  File "/usr/local/lib/python3.7/site-packages/requests/models.py", line 313, in prepare
    self.prepare_url(url, params)
  File "/usr/local/lib/python3.7/site-packages/requests/models.py", line 387, in prepare_url
    raise MissingSchema(error)
requests.exceptions.MissingSchema: Invalid URL '//img5.mtime.cn/mg/2017/04/06/151753.33911673_270X405X4.jpg': No schema supplied. Perhaps you meant http:////img5.mtime.cn/mg/2017/04/06/151753.33911673_270X405X4.jpg?

[2019-12-28 13:50:19] name:金刚：骷髅岛 url:https://91mjw.com/all/page/28 Invalid URL '//img5.mtime.cn/mg/2017/02/27/104631.11443566_270X405X4.jpg': No schema supplied. Perhaps you meant http:////img5.mtime.cn/mg/2017/02/27/104631.11443566_270X405X4.jpg?
Traceback (most recent call last):
  File "91.py", line 100, in <module>
    img_file = requests.get(cover_picture_origin).content
  File "/usr/local/lib/python3.7/site-packages/requests/api.py", line 75, in get
    return request('get', url, params=params, **kwargs)
  File "/usr/local/lib/python3.7/site-packages/requests/api.py", line 60, in request
    return session.request(method=method, url=url, **kwargs)
  File "/usr/local/lib/python3.7/site-packages/requests/sessions.py", line 519, in request
    prep = self.prepare_request(req)
  File "/usr/local/lib/python3.7/site-packages/requests/sessions.py", line 462, in prepare_request
    hooks=merge_hooks(request.hooks, self.hooks),
  File "/usr/local/lib/python3.7/site-packages/requests/models.py", line 313, in prepare
    self.prepare_url(url, params)
  File "/usr/local/lib/python3.7/site-packages/requests/models.py", line 387, in prepare_url
    raise MissingSchema(error)
requests.exceptions.MissingSchema: Invalid URL '//img5.mtime.cn/mg/2017/02/27/104631.11443566_270X405X4.jpg': No schema supplied. Perhaps you meant http:////img5.mtime.cn/mg/2017/02/27/104631.11443566_270X405X4.jpg?

[2019-12-28 13:50:48] name:金刚狼3 url:https://91mjw.com/all/page/29 Invalid URL '//img5.mtime.cn/mg/2017/02/28/112615.77378230_270X405X4.jpg': No schema supplied. Perhaps you meant http:////img5.mtime.cn/mg/2017/02/28/112615.77378230_270X405X4.jpg?
Traceback (most recent call last):
  File "91.py", line 100, in <module>
    img_file = requests.get(cover_picture_origin).content
  File "/usr/local/lib/python3.7/site-packages/requests/api.py", line 75, in get
    return request('get', url, params=params, **kwargs)
  File "/usr/local/lib/python3.7/site-packages/requests/api.py", line 60, in request
    return session.request(method=method, url=url, **kwargs)
  File "/usr/local/lib/python3.7/site-packages/requests/sessions.py", line 519, in request
    prep = self.prepare_request(req)
  File "/usr/local/lib/python3.7/site-packages/requests/sessions.py", line 462, in prepare_request
    hooks=merge_hooks(request.hooks, self.hooks),
  File "/usr/local/lib/python3.7/site-packages/requests/models.py", line 313, in prepare
    self.prepare_url(url, params)
  File "/usr/local/lib/python3.7/site-packages/requests/models.py", line 387, in prepare_url
    raise MissingSchema(error)
requests.exceptions.MissingSchema: Invalid URL '//img5.mtime.cn/mg/2017/02/28/112615.77378230_270X405X4.jpg': No schema supplied. Perhaps you meant http:////img5.mtime.cn/mg/2017/02/28/112615.77378230_270X405X4.jpg?

[2019-12-28 13:51:46] name:缘起泽尔达 url:https://91mjw.com/all/page/29 Invalid URL '//img5.mtime.cn/mt/2016/12/27/152024.33337562_270X405X4.jpg': No schema supplied. Perhaps you meant http:////img5.mtime.cn/mt/2016/12/27/152024.33337562_270X405X4.jpg?
Traceback (most recent call last):
  File "91.py", line 100, in <module>
    img_file = requests.get(cover_picture_origin).content
  File "/usr/local/lib/python3.7/site-packages/requests/api.py", line 75, in get
    return request('get', url, params=params, **kwargs)
  File "/usr/local/lib/python3.7/site-packages/requests/api.py", line 60, in request
    return session.request(method=method, url=url, **kwargs)
  File "/usr/local/lib/python3.7/site-packages/requests/sessions.py", line 519, in request
    prep = self.prepare_request(req)
  File "/usr/local/lib/python3.7/site-packages/requests/sessions.py", line 462, in prepare_request
    hooks=merge_hooks(request.hooks, self.hooks),
  File "/usr/local/lib/python3.7/site-packages/requests/models.py", line 313, in prepare
    self.prepare_url(url, params)
  File "/usr/local/lib/python3.7/site-packages/requests/models.py", line 387, in prepare_url
    raise MissingSchema(error)
requests.exceptions.MissingSchema: Invalid URL '//img5.mtime.cn/mt/2016/12/27/152024.33337562_270X405X4.jpg': No schema supplied. Perhaps you meant http:////img5.mtime.cn/mt/2016/12/27/152024.33337562_270X405X4.jpg?

[2019-12-28 13:53:28] name:佩小姐的奇幻城堡 url:https://91mjw.com/all/page/30 Invalid URL '//img5.mtime.cn/mg/2016/11/17/170552.14009482_270X405X4.jpg': No schema supplied. Perhaps you meant http:////img5.mtime.cn/mg/2016/11/17/170552.14009482_270X405X4.jpg?
Traceback (most recent call last):
  File "91.py", line 100, in <module>
    img_file = requests.get(cover_picture_origin).content
  File "/usr/local/lib/python3.7/site-packages/requests/api.py", line 75, in get
    return request('get', url, params=params, **kwargs)
  File "/usr/local/lib/python3.7/site-packages/requests/api.py", line 60, in request
    return session.request(method=method, url=url, **kwargs)
  File "/usr/local/lib/python3.7/site-packages/requests/sessions.py", line 519, in request
    prep = self.prepare_request(req)
  File "/usr/local/lib/python3.7/site-packages/requests/sessions.py", line 462, in prepare_request
    hooks=merge_hooks(request.hooks, self.hooks),
  File "/usr/local/lib/python3.7/site-packages/requests/models.py", line 313, in prepare
    self.prepare_url(url, params)
  File "/usr/local/lib/python3.7/site-packages/requests/models.py", line 387, in prepare_url
    raise MissingSchema(error)
requests.exceptions.MissingSchema: Invalid URL '//img5.mtime.cn/mg/2016/11/17/170552.14009482_270X405X4.jpg': No schema supplied. Perhaps you meant http:////img5.mtime.cn/mg/2016/11/17/170552.14009482_270X405X4.jpg?

[2019-12-28 13:53:45] name:少狼.Teen.Wolf.S06E20.END.中英字幕.WEB-HR.AAC.720P.X264-人人影视.mp4 url:https://91mjw.com/all/page/30 HTTPSConnectionPool(host='img21.mtime.cn', port=443): Max retries exceeded with url: /pi/2011/11/02/141038.92348380_1000X1000.jpg (Caused by SSLError(SSLCertVerificationError(1, '[SSL: CERTIFICATE_VERIFY_FAILED] certificate verify failed: unable to get local issuer certificate (_ssl.c:1076)')))
Traceback (most recent call last):
  File "/usr/local/lib/python3.7/site-packages/urllib3/connectionpool.py", line 662, in urlopen
    self._prepare_proxy(conn)
  File "/usr/local/lib/python3.7/site-packages/urllib3/connectionpool.py", line 948, in _prepare_proxy
    conn.connect()
  File "/usr/local/lib/python3.7/site-packages/urllib3/connection.py", line 394, in connect
    ssl_context=context,
  File "/usr/local/lib/python3.7/site-packages/urllib3/util/ssl_.py", line 370, in ssl_wrap_socket
    return context.wrap_socket(sock, server_hostname=server_hostname)
  File "/usr/local/Cellar/python/3.7.4_1/Frameworks/Python.framework/Versions/3.7/lib/python3.7/ssl.py", line 423, in wrap_socket
    session=session
  File "/usr/local/Cellar/python/3.7.4_1/Frameworks/Python.framework/Versions/3.7/lib/python3.7/ssl.py", line 870, in _create
    self.do_handshake()
  File "/usr/local/Cellar/python/3.7.4_1/Frameworks/Python.framework/Versions/3.7/lib/python3.7/ssl.py", line 1139, in do_handshake
    self._sslobj.do_handshake()
ssl.SSLCertVerificationError: [SSL: CERTIFICATE_VERIFY_FAILED] certificate verify failed: unable to get local issuer certificate (_ssl.c:1076)

During handling of the above exception, another exception occurred:

Traceback (most recent call last):
  File "/usr/local/lib/python3.7/site-packages/requests/adapters.py", line 449, in send
    timeout=timeout
  File "/usr/local/lib/python3.7/site-packages/urllib3/connectionpool.py", line 720, in urlopen
    method, url, error=e, _pool=self, _stacktrace=sys.exc_info()[2]
  File "/usr/local/lib/python3.7/site-packages/urllib3/util/retry.py", line 436, in increment
    raise MaxRetryError(_pool, url, error or ResponseError(cause))
urllib3.exceptions.MaxRetryError: HTTPSConnectionPool(host='img21.mtime.cn', port=443): Max retries exceeded with url: /pi/2011/11/02/141038.92348380_1000X1000.jpg (Caused by SSLError(SSLCertVerificationError(1, '[SSL: CERTIFICATE_VERIFY_FAILED] certificate verify failed: unable to get local issuer certificate (_ssl.c:1076)')))

During handling of the above exception, another exception occurred:

Traceback (most recent call last):
  File "91.py", line 149, in <module>
    img_file = requests.get(img['data-original']).content
  File "/usr/local/lib/python3.7/site-packages/requests/api.py", line 75, in get
    return request('get', url, params=params, **kwargs)
  File "/usr/local/lib/python3.7/site-packages/requests/api.py", line 60, in request
    return session.request(method=method, url=url, **kwargs)
  File "/usr/local/lib/python3.7/site-packages/requests/sessions.py", line 533, in request
    resp = self.send(prep, **send_kwargs)
  File "/usr/local/lib/python3.7/site-packages/requests/sessions.py", line 646, in send
    r = adapter.send(request, **kwargs)
  File "/usr/local/lib/python3.7/site-packages/requests/adapters.py", line 514, in send
    raise SSLError(e, request=request)
requests.exceptions.SSLError: HTTPSConnectionPool(host='img21.mtime.cn', port=443): Max retries exceeded with url: /pi/2011/11/02/141038.92348380_1000X1000.jpg (Caused by SSLError(SSLCertVerificationError(1, '[SSL: CERTIFICATE_VERIFY_FAILED] certificate verify failed: unable to get local issuer certificate (_ssl.c:1076)')))

[2019-12-28 13:53:53] name:奇异博士 url:https://91mjw.com/all/page/30 Invalid URL '//img5.mtime.cn/mg/2016/10/10/160212.45410947_270X405X4.jpg': No schema supplied. Perhaps you meant http:////img5.mtime.cn/mg/2016/10/10/160212.45410947_270X405X4.jpg?
Traceback (most recent call last):
  File "91.py", line 100, in <module>
    img_file = requests.get(cover_picture_origin).content
  File "/usr/local/lib/python3.7/site-packages/requests/api.py", line 75, in get
    return request('get', url, params=params, **kwargs)
  File "/usr/local/lib/python3.7/site-packages/requests/api.py", line 60, in request
    return session.request(method=method, url=url, **kwargs)
  File "/usr/local/lib/python3.7/site-packages/requests/sessions.py", line 519, in request
    prep = self.prepare_request(req)
  File "/usr/local/lib/python3.7/site-packages/requests/sessions.py", line 462, in prepare_request
    hooks=merge_hooks(request.hooks, self.hooks),
  File "/usr/local/lib/python3.7/site-packages/requests/models.py", line 313, in prepare
    self.prepare_url(url, params)
  File "/usr/local/lib/python3.7/site-packages/requests/models.py", line 387, in prepare_url
    raise MissingSchema(error)
requests.exceptions.MissingSchema: Invalid URL '//img5.mtime.cn/mg/2016/10/10/160212.45410947_270X405X4.jpg': No schema supplied. Perhaps you meant http:////img5.mtime.cn/mg/2016/10/10/160212.45410947_270X405X4.jpg?

[2019-12-28 13:55:14] name:打工姐妹花.2.Broke.Girls.S06E22.END.中英字幕.WEB-HR.AAC.1024X576.x264-人人影视.v2.mp4 url:https://91mjw.com/all/page/31 Invalid URL '//img31.mtime.cn/pi/2013/10/02/151857.66040461_1000X1000.jpg': No schema supplied. Perhaps you meant http:////img31.mtime.cn/pi/2013/10/02/151857.66040461_1000X1000.jpg?
Traceback (most recent call last):
  File "91.py", line 149, in <module>
    img_file = requests.get(img['data-original']).content
  File "/usr/local/lib/python3.7/site-packages/requests/api.py", line 75, in get
    return request('get', url, params=params, **kwargs)
  File "/usr/local/lib/python3.7/site-packages/requests/api.py", line 60, in request
    return session.request(method=method, url=url, **kwargs)
  File "/usr/local/lib/python3.7/site-packages/requests/sessions.py", line 519, in request
    prep = self.prepare_request(req)
  File "/usr/local/lib/python3.7/site-packages/requests/sessions.py", line 462, in prepare_request
    hooks=merge_hooks(request.hooks, self.hooks),
  File "/usr/local/lib/python3.7/site-packages/requests/models.py", line 313, in prepare
    self.prepare_url(url, params)
  File "/usr/local/lib/python3.7/site-packages/requests/models.py", line 387, in prepare_url
    raise MissingSchema(error)
requests.exceptions.MissingSchema: Invalid URL '//img31.mtime.cn/pi/2013/10/02/151857.66040461_1000X1000.jpg': No schema supplied. Perhaps you meant http:////img31.mtime.cn/pi/2013/10/02/151857.66040461_1000X1000.jpg?

[2019-12-28 13:55:34] name:定罪 url:https://91mjw.com/all/page/31 Invalid URL '//img5.mtime.cn/mg/2016/09/30/100406.26413234_270X405X4.jpg': No schema supplied. Perhaps you meant http:////img5.mtime.cn/mg/2016/09/30/100406.26413234_270X405X4.jpg?
Traceback (most recent call last):
  File "91.py", line 100, in <module>
    img_file = requests.get(cover_picture_origin).content
  File "/usr/local/lib/python3.7/site-packages/requests/api.py", line 75, in get
    return request('get', url, params=params, **kwargs)
  File "/usr/local/lib/python3.7/site-packages/requests/api.py", line 60, in request
    return session.request(method=method, url=url, **kwargs)
  File "/usr/local/lib/python3.7/site-packages/requests/sessions.py", line 519, in request
    prep = self.prepare_request(req)
  File "/usr/local/lib/python3.7/site-packages/requests/sessions.py", line 462, in prepare_request
    hooks=merge_hooks(request.hooks, self.hooks),
  File "/usr/local/lib/python3.7/site-packages/requests/models.py", line 313, in prepare
    self.prepare_url(url, params)
  File "/usr/local/lib/python3.7/site-packages/requests/models.py", line 387, in prepare_url
    raise MissingSchema(error)
requests.exceptions.MissingSchema: Invalid URL '//img5.mtime.cn/mg/2016/09/30/100406.26413234_270X405X4.jpg': No schema supplied. Perhaps you meant http:////img5.mtime.cn/mg/2016/09/30/100406.26413234_270X405X4.jpg?

[2019-12-28 13:55:51] name:卢克·凯奇 url:https://91mjw.com/all/page/31 'NoneType' object is not subscriptable
Traceback (most recent call last):
  File "91.py", line 117, in <module>
    title, name, str(director), str(scriptwriter), str(cast), category, cat_id[0],
TypeError: 'NoneType' object is not subscriptable

[2019-12-28 13:57:13] name:指定幸存者 url:https://91mjw.com/all/page/32 Invalid URL '//img31.mtime.cn/mg/2016/09/04/165028.15330685_270X405X4.jpg': No schema supplied. Perhaps you meant http:////img31.mtime.cn/mg/2016/09/04/165028.15330685_270X405X4.jpg?
Traceback (most recent call last):
  File "91.py", line 100, in <module>
    img_file = requests.get(cover_picture_origin).content
  File "/usr/local/lib/python3.7/site-packages/requests/api.py", line 75, in get
    return request('get', url, params=params, **kwargs)
  File "/usr/local/lib/python3.7/site-packages/requests/api.py", line 60, in request
    return session.request(method=method, url=url, **kwargs)
  File "/usr/local/lib/python3.7/site-packages/requests/sessions.py", line 519, in request
    prep = self.prepare_request(req)
  File "/usr/local/lib/python3.7/site-packages/requests/sessions.py", line 462, in prepare_request
    hooks=merge_hooks(request.hooks, self.hooks),
  File "/usr/local/lib/python3.7/site-packages/requests/models.py", line 313, in prepare
    self.prepare_url(url, params)
  File "/usr/local/lib/python3.7/site-packages/requests/models.py", line 387, in prepare_url
    raise MissingSchema(error)
requests.exceptions.MissingSchema: Invalid URL '//img31.mtime.cn/mg/2016/09/04/165028.15330685_270X405X4.jpg': No schema supplied. Perhaps you meant http:////img31.mtime.cn/mg/2016/09/04/165028.15330685_270X405X4.jpg?

[2019-12-28 13:57:20] name:我们的生活.This.Is.Us.S01E18.End.中英字幕.WEB-HR.AAC.720P.x264-人人影视.mp4 url:https://91mjw.com/all/page/32 Invalid URL 'http:///img5.mtime.cn/pi/2016/09/30/183750.35554831_1000X1000.jpg': No host supplied
Traceback (most recent call last):
  File "91.py", line 149, in <module>
    img_file = requests.get(img['data-original']).content
  File "/usr/local/lib/python3.7/site-packages/requests/api.py", line 75, in get
    return request('get', url, params=params, **kwargs)
  File "/usr/local/lib/python3.7/site-packages/requests/api.py", line 60, in request
    return session.request(method=method, url=url, **kwargs)
  File "/usr/local/lib/python3.7/site-packages/requests/sessions.py", line 519, in request
    prep = self.prepare_request(req)
  File "/usr/local/lib/python3.7/site-packages/requests/sessions.py", line 462, in prepare_request
    hooks=merge_hooks(request.hooks, self.hooks),
  File "/usr/local/lib/python3.7/site-packages/requests/models.py", line 313, in prepare
    self.prepare_url(url, params)
  File "/usr/local/lib/python3.7/site-packages/requests/models.py", line 390, in prepare_url
    raise InvalidURL("Invalid URL %r: No host supplied" % url)
requests.exceptions.InvalidURL: Invalid URL 'http:///img5.mtime.cn/pi/2016/09/30/183750.35554831_1000X1000.jpg': No host supplied

[2019-12-28 14:00:48] name:X战警：天启 url:https://91mjw.com/all/page/33 Invalid URL '//img31.mtime.cn/mg/2016/05/25/161359.70256214_270X405X4.jpg': No schema supplied. Perhaps you meant http:////img31.mtime.cn/mg/2016/05/25/161359.70256214_270X405X4.jpg?
Traceback (most recent call last):
  File "91.py", line 100, in <module>
    img_file = requests.get(cover_picture_origin).content
  File "/usr/local/lib/python3.7/site-packages/requests/api.py", line 75, in get
    return request('get', url, params=params, **kwargs)
  File "/usr/local/lib/python3.7/site-packages/requests/api.py", line 60, in request
    return session.request(method=method, url=url, **kwargs)
  File "/usr/local/lib/python3.7/site-packages/requests/sessions.py", line 519, in request
    prep = self.prepare_request(req)
  File "/usr/local/lib/python3.7/site-packages/requests/sessions.py", line 462, in prepare_request
    hooks=merge_hooks(request.hooks, self.hooks),
  File "/usr/local/lib/python3.7/site-packages/requests/models.py", line 313, in prepare
    self.prepare_url(url, params)
  File "/usr/local/lib/python3.7/site-packages/requests/models.py", line 387, in prepare_url
    raise MissingSchema(error)
requests.exceptions.MissingSchema: Invalid URL '//img31.mtime.cn/mg/2016/05/25/161359.70256214_270X405X4.jpg': No schema supplied. Perhaps you meant http:////img31.mtime.cn/mg/2016/05/25/161359.70256214_270X405X4.jpg?

[2019-12-28 14:01:02] name:传教士.Preacher.S01E10.中英字幕.BD-HR.AAC.1024X576.x264.mp4 url:https://91mjw.com/all/page/33 Invalid URL '//img31.mtime.cn/pi/2016/06/14/144258.63550934_1000X1000.jpg': No schema supplied. Perhaps you meant http:////img31.mtime.cn/pi/2016/06/14/144258.63550934_1000X1000.jpg?
Traceback (most recent call last):
  File "91.py", line 149, in <module>
    img_file = requests.get(img['data-original']).content
  File "/usr/local/lib/python3.7/site-packages/requests/api.py", line 75, in get
    return request('get', url, params=params, **kwargs)
  File "/usr/local/lib/python3.7/site-packages/requests/api.py", line 60, in request
    return session.request(method=method, url=url, **kwargs)
  File "/usr/local/lib/python3.7/site-packages/requests/sessions.py", line 519, in request
    prep = self.prepare_request(req)
  File "/usr/local/lib/python3.7/site-packages/requests/sessions.py", line 462, in prepare_request
    hooks=merge_hooks(request.hooks, self.hooks),
  File "/usr/local/lib/python3.7/site-packages/requests/models.py", line 313, in prepare
    self.prepare_url(url, params)
  File "/usr/local/lib/python3.7/site-packages/requests/models.py", line 387, in prepare_url
    raise MissingSchema(error)
requests.exceptions.MissingSchema: Invalid URL '//img31.mtime.cn/pi/2016/06/14/144258.63550934_1000X1000.jpg': No schema supplied. Perhaps you meant http:////img31.mtime.cn/pi/2016/06/14/144258.63550934_1000X1000.jpg?

[2019-12-28 14:04:18] name:海蒂和爷爷 url:https://91mjw.com/all/page/35 Invalid URL '//img31.mtime.cn/mg/2016/06/15/164819.45866579_270X405X4.jpg': No schema supplied. Perhaps you meant http:////img31.mtime.cn/mg/2016/06/15/164819.45866579_270X405X4.jpg?
Traceback (most recent call last):
  File "91.py", line 100, in <module>
    img_file = requests.get(cover_picture_origin).content
  File "/usr/local/lib/python3.7/site-packages/requests/api.py", line 75, in get
    return request('get', url, params=params, **kwargs)
  File "/usr/local/lib/python3.7/site-packages/requests/api.py", line 60, in request
    return session.request(method=method, url=url, **kwargs)
  File "/usr/local/lib/python3.7/site-packages/requests/sessions.py", line 519, in request
    prep = self.prepare_request(req)
  File "/usr/local/lib/python3.7/site-packages/requests/sessions.py", line 462, in prepare_request
    hooks=merge_hooks(request.hooks, self.hooks),
  File "/usr/local/lib/python3.7/site-packages/requests/models.py", line 313, in prepare
    self.prepare_url(url, params)
  File "/usr/local/lib/python3.7/site-packages/requests/models.py", line 387, in prepare_url
    raise MissingSchema(error)
requests.exceptions.MissingSchema: Invalid URL '//img31.mtime.cn/mg/2016/06/15/164819.45866579_270X405X4.jpg': No schema supplied. Perhaps you meant http:////img31.mtime.cn/mg/2016/06/15/164819.45866579_270X405X4.jpg?

[2019-12-28 14:05:27] name:打工姐妹花.2.Broke.Girls.S05E22.END.中英字幕.HR-HDTV.AAC.1024X576.x264.mp4 url:https://91mjw.com/all/page/36 Invalid URL '//img31.mtime.cn/pi/2013/10/02/151857.66040461_1000X1000.jpg': No schema supplied. Perhaps you meant http:////img31.mtime.cn/pi/2013/10/02/151857.66040461_1000X1000.jpg?
Traceback (most recent call last):
  File "91.py", line 149, in <module>
    img_file = requests.get(img['data-original']).content
  File "/usr/local/lib/python3.7/site-packages/requests/api.py", line 75, in get
    return request('get', url, params=params, **kwargs)
  File "/usr/local/lib/python3.7/site-packages/requests/api.py", line 60, in request
    return session.request(method=method, url=url, **kwargs)
  File "/usr/local/lib/python3.7/site-packages/requests/sessions.py", line 519, in request
    prep = self.prepare_request(req)
  File "/usr/local/lib/python3.7/site-packages/requests/sessions.py", line 462, in prepare_request
    hooks=merge_hooks(request.hooks, self.hooks),
  File "/usr/local/lib/python3.7/site-packages/requests/models.py", line 313, in prepare
    self.prepare_url(url, params)
  File "/usr/local/lib/python3.7/site-packages/requests/models.py", line 387, in prepare_url
    raise MissingSchema(error)
requests.exceptions.MissingSchema: Invalid URL '//img31.mtime.cn/pi/2013/10/02/151857.66040461_1000X1000.jpg': No schema supplied. Perhaps you meant http:////img31.mtime.cn/pi/2013/10/02/151857.66040461_1000X1000.jpg?

[2019-12-28 14:06:29] name:边境杀手 url:https://91mjw.com/all/page/36 Invalid URL '//img31.mtime.cn/mg/2015/07/30/110159.23310293_270X405X4.jpg': No schema supplied. Perhaps you meant http:////img31.mtime.cn/mg/2015/07/30/110159.23310293_270X405X4.jpg?
Traceback (most recent call last):
  File "91.py", line 100, in <module>
    img_file = requests.get(cover_picture_origin).content
  File "/usr/local/lib/python3.7/site-packages/requests/api.py", line 75, in get
    return request('get', url, params=params, **kwargs)
  File "/usr/local/lib/python3.7/site-packages/requests/api.py", line 60, in request
    return session.request(method=method, url=url, **kwargs)
  File "/usr/local/lib/python3.7/site-packages/requests/sessions.py", line 519, in request
    prep = self.prepare_request(req)
  File "/usr/local/lib/python3.7/site-packages/requests/sessions.py", line 462, in prepare_request
    hooks=merge_hooks(request.hooks, self.hooks),
  File "/usr/local/lib/python3.7/site-packages/requests/models.py", line 313, in prepare
    self.prepare_url(url, params)
  File "/usr/local/lib/python3.7/site-packages/requests/models.py", line 387, in prepare_url
    raise MissingSchema(error)
requests.exceptions.MissingSchema: Invalid URL '//img31.mtime.cn/mg/2015/07/30/110159.23310293_270X405X4.jpg': No schema supplied. Perhaps you meant http:////img31.mtime.cn/mg/2015/07/30/110159.23310293_270X405X4.jpg?

[2019-12-28 14:09:05] name:终结者5 url:https://91mjw.com/all/page/37 Invalid URL '//img31.mtime.cn/mg/2015/08/26/094558.28841213_270X405X4.jpg': No schema supplied. Perhaps you meant http:////img31.mtime.cn/mg/2015/08/26/094558.28841213_270X405X4.jpg?
Traceback (most recent call last):
  File "91.py", line 100, in <module>
    img_file = requests.get(cover_picture_origin).content
  File "/usr/local/lib/python3.7/site-packages/requests/api.py", line 75, in get
    return request('get', url, params=params, **kwargs)
  File "/usr/local/lib/python3.7/site-packages/requests/api.py", line 60, in request
    return session.request(method=method, url=url, **kwargs)
  File "/usr/local/lib/python3.7/site-packages/requests/sessions.py", line 519, in request
    prep = self.prepare_request(req)
  File "/usr/local/lib/python3.7/site-packages/requests/sessions.py", line 462, in prepare_request
    hooks=merge_hooks(request.hooks, self.hooks),
  File "/usr/local/lib/python3.7/site-packages/requests/models.py", line 313, in prepare
    self.prepare_url(url, params)
  File "/usr/local/lib/python3.7/site-packages/requests/models.py", line 387, in prepare_url
    raise MissingSchema(error)
requests.exceptions.MissingSchema: Invalid URL '//img31.mtime.cn/mg/2015/08/26/094558.28841213_270X405X4.jpg': No schema supplied. Perhaps you meant http:////img31.mtime.cn/mg/2015/08/26/094558.28841213_270X405X4.jpg?

[2019-12-28 14:13:16] name:星际穿越 url:https://91mjw.com/all/page/39 Invalid URL '//img31.mtime.cn/mg/2014/10/17/094153.87490459_270X405X4.jpg': No schema supplied. Perhaps you meant http:////img31.mtime.cn/mg/2014/10/17/094153.87490459_270X405X4.jpg?
Traceback (most recent call last):
  File "91.py", line 100, in <module>
    img_file = requests.get(cover_picture_origin).content
  File "/usr/local/lib/python3.7/site-packages/requests/api.py", line 75, in get
    return request('get', url, params=params, **kwargs)
  File "/usr/local/lib/python3.7/site-packages/requests/api.py", line 60, in request
    return session.request(method=method, url=url, **kwargs)
  File "/usr/local/lib/python3.7/site-packages/requests/sessions.py", line 519, in request
    prep = self.prepare_request(req)
  File "/usr/local/lib/python3.7/site-packages/requests/sessions.py", line 462, in prepare_request
    hooks=merge_hooks(request.hooks, self.hooks),
  File "/usr/local/lib/python3.7/site-packages/requests/models.py", line 313, in prepare
    self.prepare_url(url, params)
  File "/usr/local/lib/python3.7/site-packages/requests/models.py", line 387, in prepare_url
    raise MissingSchema(error)
requests.exceptions.MissingSchema: Invalid URL '//img31.mtime.cn/mg/2014/10/17/094153.87490459_270X405X4.jpg': No schema supplied. Perhaps you meant http:////img31.mtime.cn/mg/2014/10/17/094153.87490459_270X405X4.jpg?

[2019-12-28 14:13:40] name:打工姐妹花.2.Broke.Girls.S04E22.中英字幕.WEB-HR.AC3.1024X576.x264.mkv url:https://91mjw.com/all/page/39 Invalid URL '//img21.mtime.cn/pi/2012/02/28/140603.93186131_1000X1000.jpg': No schema supplied. Perhaps you meant http:////img21.mtime.cn/pi/2012/02/28/140603.93186131_1000X1000.jpg?
Traceback (most recent call last):
  File "91.py", line 149, in <module>
    img_file = requests.get(img['data-original']).content
  File "/usr/local/lib/python3.7/site-packages/requests/api.py", line 75, in get
    return request('get', url, params=params, **kwargs)
  File "/usr/local/lib/python3.7/site-packages/requests/api.py", line 60, in request
    return session.request(method=method, url=url, **kwargs)
  File "/usr/local/lib/python3.7/site-packages/requests/sessions.py", line 519, in request
    prep = self.prepare_request(req)
  File "/usr/local/lib/python3.7/site-packages/requests/sessions.py", line 462, in prepare_request
    hooks=merge_hooks(request.hooks, self.hooks),
  File "/usr/local/lib/python3.7/site-packages/requests/models.py", line 313, in prepare
    self.prepare_url(url, params)
  File "/usr/local/lib/python3.7/site-packages/requests/models.py", line 387, in prepare_url
    raise MissingSchema(error)
requests.exceptions.MissingSchema: Invalid URL '//img21.mtime.cn/pi/2012/02/28/140603.93186131_1000X1000.jpg': No schema supplied. Perhaps you meant http:////img21.mtime.cn/pi/2012/02/28/140603.93186131_1000X1000.jpg?

[2019-12-28 14:14:03] name:银河护卫队 url:https://91mjw.com/all/page/39 Invalid URL '//img31.mtime.cn/mg/2014/09/01/093630.14934540_270X405X4.jpg': No schema supplied. Perhaps you meant http:////img31.mtime.cn/mg/2014/09/01/093630.14934540_270X405X4.jpg?
Traceback (most recent call last):
  File "91.py", line 100, in <module>
    img_file = requests.get(cover_picture_origin).content
  File "/usr/local/lib/python3.7/site-packages/requests/api.py", line 75, in get
    return request('get', url, params=params, **kwargs)
  File "/usr/local/lib/python3.7/site-packages/requests/api.py", line 60, in request
    return session.request(method=method, url=url, **kwargs)
  File "/usr/local/lib/python3.7/site-packages/requests/sessions.py", line 519, in request
    prep = self.prepare_request(req)
  File "/usr/local/lib/python3.7/site-packages/requests/sessions.py", line 462, in prepare_request
    hooks=merge_hooks(request.hooks, self.hooks),
  File "/usr/local/lib/python3.7/site-packages/requests/models.py", line 313, in prepare
    self.prepare_url(url, params)
  File "/usr/local/lib/python3.7/site-packages/requests/models.py", line 387, in prepare_url
    raise MissingSchema(error)
requests.exceptions.MissingSchema: Invalid URL '//img31.mtime.cn/mg/2014/09/01/093630.14934540_270X405X4.jpg': No schema supplied. Perhaps you meant http:////img31.mtime.cn/mg/2014/09/01/093630.14934540_270X405X4.jpg?

[2019-12-28 14:15:07] name:伸冤人 url:https://91mjw.com/all/page/40 Invalid URL '//img31.mtime.cn/mg/2014/07/17/094231.32471336_270X405X4.jpg': No schema supplied. Perhaps you meant http:////img31.mtime.cn/mg/2014/07/17/094231.32471336_270X405X4.jpg?
Traceback (most recent call last):
  File "91.py", line 100, in <module>
    img_file = requests.get(cover_picture_origin).content
  File "/usr/local/lib/python3.7/site-packages/requests/api.py", line 75, in get
    return request('get', url, params=params, **kwargs)
  File "/usr/local/lib/python3.7/site-packages/requests/api.py", line 60, in request
    return session.request(method=method, url=url, **kwargs)
  File "/usr/local/lib/python3.7/site-packages/requests/sessions.py", line 519, in request
    prep = self.prepare_request(req)
  File "/usr/local/lib/python3.7/site-packages/requests/sessions.py", line 462, in prepare_request
    hooks=merge_hooks(request.hooks, self.hooks),
  File "/usr/local/lib/python3.7/site-packages/requests/models.py", line 313, in prepare
    self.prepare_url(url, params)
  File "/usr/local/lib/python3.7/site-packages/requests/models.py", line 387, in prepare_url
    raise MissingSchema(error)
requests.exceptions.MissingSchema: Invalid URL '//img31.mtime.cn/mg/2014/07/17/094231.32471336_270X405X4.jpg': No schema supplied. Perhaps you meant http:////img31.mtime.cn/mg/2014/07/17/094231.32471336_270X405X4.jpg?

[2019-12-28 14:17:51] name:X战警：逆转未来 url:https://91mjw.com/all/page/41 Invalid URL '//img31.mtime.cn/mg/2015/05/18/155758.64082431_270X405X4.jpg': No schema supplied. Perhaps you meant http:////img31.mtime.cn/mg/2015/05/18/155758.64082431_270X405X4.jpg?
Traceback (most recent call last):
  File "91.py", line 100, in <module>
    img_file = requests.get(cover_picture_origin).content
  File "/usr/local/lib/python3.7/site-packages/requests/api.py", line 75, in get
    return request('get', url, params=params, **kwargs)
  File "/usr/local/lib/python3.7/site-packages/requests/api.py", line 60, in request
    return session.request(method=method, url=url, **kwargs)
  File "/usr/local/lib/python3.7/site-packages/requests/sessions.py", line 519, in request
    prep = self.prepare_request(req)
  File "/usr/local/lib/python3.7/site-packages/requests/sessions.py", line 462, in prepare_request
    hooks=merge_hooks(request.hooks, self.hooks),
  File "/usr/local/lib/python3.7/site-packages/requests/models.py", line 313, in prepare
    self.prepare_url(url, params)
  File "/usr/local/lib/python3.7/site-packages/requests/models.py", line 387, in prepare_url
    raise MissingSchema(error)
requests.exceptions.MissingSchema: Invalid URL '//img31.mtime.cn/mg/2015/05/18/155758.64082431_270X405X4.jpg': No schema supplied. Perhaps you meant http:////img31.mtime.cn/mg/2015/05/18/155758.64082431_270X405X4.jpg?

[2019-12-28 14:22:24] name:打工姐妹花.2.Broke.Girls.S03E24.中英字幕.HDTVrip.1024X576.mkv url:https://91mjw.com/all/page/43 Invalid URL '//img21.mtime.cn/pi/2012/02/28/140751.49346753_1000X1000.jpg': No schema supplied. Perhaps you meant http:////img21.mtime.cn/pi/2012/02/28/140751.49346753_1000X1000.jpg?
Traceback (most recent call last):
  File "91.py", line 149, in <module>
    img_file = requests.get(img['data-original']).content
  File "/usr/local/lib/python3.7/site-packages/requests/api.py", line 75, in get
    return request('get', url, params=params, **kwargs)
  File "/usr/local/lib/python3.7/site-packages/requests/api.py", line 60, in request
    return session.request(method=method, url=url, **kwargs)
  File "/usr/local/lib/python3.7/site-packages/requests/sessions.py", line 519, in request
    prep = self.prepare_request(req)
  File "/usr/local/lib/python3.7/site-packages/requests/sessions.py", line 462, in prepare_request
    hooks=merge_hooks(request.hooks, self.hooks),
  File "/usr/local/lib/python3.7/site-packages/requests/models.py", line 313, in prepare
    self.prepare_url(url, params)
  File "/usr/local/lib/python3.7/site-packages/requests/models.py", line 387, in prepare_url
    raise MissingSchema(error)
requests.exceptions.MissingSchema: Invalid URL '//img21.mtime.cn/pi/2012/02/28/140751.49346753_1000X1000.jpg': No schema supplied. Perhaps you meant http:////img21.mtime.cn/pi/2012/02/28/140751.49346753_1000X1000.jpg?

[2019-12-28 14:23:03] name:金刚狼2 url:https://91mjw.com/all/page/43 Invalid URL '//img31.mtime.cn/mg/2014/02/25/184538.58222649_270X405X4.jpg': No schema supplied. Perhaps you meant http:////img31.mtime.cn/mg/2014/02/25/184538.58222649_270X405X4.jpg?
Traceback (most recent call last):
  File "91.py", line 100, in <module>
    img_file = requests.get(cover_picture_origin).content
  File "/usr/local/lib/python3.7/site-packages/requests/api.py", line 75, in get
    return request('get', url, params=params, **kwargs)
  File "/usr/local/lib/python3.7/site-packages/requests/api.py", line 60, in request
    return session.request(method=method, url=url, **kwargs)
  File "/usr/local/lib/python3.7/site-packages/requests/sessions.py", line 519, in request
    prep = self.prepare_request(req)
  File "/usr/local/lib/python3.7/site-packages/requests/sessions.py", line 462, in prepare_request
    hooks=merge_hooks(request.hooks, self.hooks),
  File "/usr/local/lib/python3.7/site-packages/requests/models.py", line 313, in prepare
    self.prepare_url(url, params)
  File "/usr/local/lib/python3.7/site-packages/requests/models.py", line 387, in prepare_url
    raise MissingSchema(error)
requests.exceptions.MissingSchema: Invalid URL '//img31.mtime.cn/mg/2014/02/25/184538.58222649_270X405X4.jpg': No schema supplied. Perhaps you meant http:////img31.mtime.cn/mg/2014/02/25/184538.58222649_270X405X4.jpg?

[2019-12-28 14:23:08] name:女子监狱.Orange.Is.The.New.Black.S01E13.中英字幕.WEB-HR.AC3.1024X576.x264-YYeTs人人影视.mkv url:https://91mjw.com/all/page/43 HTTPSConnectionPool(host='img31.mtime.cn', port=443): Max retries exceeded with url: /pi/2013/06/08/093314.13432001_1000X1000.jpg (Caused by SSLError(SSLCertVerificationError(1, '[SSL: CERTIFICATE_VERIFY_FAILED] certificate verify failed: unable to get local issuer certificate (_ssl.c:1076)')))
Traceback (most recent call last):
  File "/usr/local/lib/python3.7/site-packages/urllib3/connectionpool.py", line 662, in urlopen
    self._prepare_proxy(conn)
  File "/usr/local/lib/python3.7/site-packages/urllib3/connectionpool.py", line 948, in _prepare_proxy
    conn.connect()
  File "/usr/local/lib/python3.7/site-packages/urllib3/connection.py", line 394, in connect
    ssl_context=context,
  File "/usr/local/lib/python3.7/site-packages/urllib3/util/ssl_.py", line 370, in ssl_wrap_socket
    return context.wrap_socket(sock, server_hostname=server_hostname)
  File "/usr/local/Cellar/python/3.7.4_1/Frameworks/Python.framework/Versions/3.7/lib/python3.7/ssl.py", line 423, in wrap_socket
    session=session
  File "/usr/local/Cellar/python/3.7.4_1/Frameworks/Python.framework/Versions/3.7/lib/python3.7/ssl.py", line 870, in _create
    self.do_handshake()
  File "/usr/local/Cellar/python/3.7.4_1/Frameworks/Python.framework/Versions/3.7/lib/python3.7/ssl.py", line 1139, in do_handshake
    self._sslobj.do_handshake()
ssl.SSLCertVerificationError: [SSL: CERTIFICATE_VERIFY_FAILED] certificate verify failed: unable to get local issuer certificate (_ssl.c:1076)

During handling of the above exception, another exception occurred:

Traceback (most recent call last):
  File "/usr/local/lib/python3.7/site-packages/requests/adapters.py", line 449, in send
    timeout=timeout
  File "/usr/local/lib/python3.7/site-packages/urllib3/connectionpool.py", line 720, in urlopen
    method, url, error=e, _pool=self, _stacktrace=sys.exc_info()[2]
  File "/usr/local/lib/python3.7/site-packages/urllib3/util/retry.py", line 436, in increment
    raise MaxRetryError(_pool, url, error or ResponseError(cause))
urllib3.exceptions.MaxRetryError: HTTPSConnectionPool(host='img31.mtime.cn', port=443): Max retries exceeded with url: /pi/2013/06/08/093314.13432001_1000X1000.jpg (Caused by SSLError(SSLCertVerificationError(1, '[SSL: CERTIFICATE_VERIFY_FAILED] certificate verify failed: unable to get local issuer certificate (_ssl.c:1076)')))

During handling of the above exception, another exception occurred:

Traceback (most recent call last):
  File "91.py", line 149, in <module>
    img_file = requests.get(img['data-original']).content
  File "/usr/local/lib/python3.7/site-packages/requests/api.py", line 75, in get
    return request('get', url, params=params, **kwargs)
  File "/usr/local/lib/python3.7/site-packages/requests/api.py", line 60, in request
    return session.request(method=method, url=url, **kwargs)
  File "/usr/local/lib/python3.7/site-packages/requests/sessions.py", line 533, in request
    resp = self.send(prep, **send_kwargs)
  File "/usr/local/lib/python3.7/site-packages/requests/sessions.py", line 646, in send
    r = adapter.send(request, **kwargs)
  File "/usr/local/lib/python3.7/site-packages/requests/adapters.py", line 514, in send
    raise SSLError(e, request=request)
requests.exceptions.SSLError: HTTPSConnectionPool(host='img31.mtime.cn', port=443): Max retries exceeded with url: /pi/2013/06/08/093314.13432001_1000X1000.jpg (Caused by SSLError(SSLCertVerificationError(1, '[SSL: CERTIFICATE_VERIFY_FAILED] certificate verify failed: unable to get local issuer certificate (_ssl.c:1076)')))

[2019-12-28 14:27:35] name:打工姐妹花.2.Broke.Girls.S02E24.Chi_Eng.WEB-HR.AC3.1024X576.x264-YYeTs人人影视.mkv url:https://91mjw.com/all/page/45 Invalid URL '//img21.mtime.cn/pi/2012/02/28/140754.27326186_1000X1000.jpg': No schema supplied. Perhaps you meant http:////img21.mtime.cn/pi/2012/02/28/140754.27326186_1000X1000.jpg?
Traceback (most recent call last):
  File "91.py", line 149, in <module>
    img_file = requests.get(img['data-original']).content
  File "/usr/local/lib/python3.7/site-packages/requests/api.py", line 75, in get
    return request('get', url, params=params, **kwargs)
  File "/usr/local/lib/python3.7/site-packages/requests/api.py", line 60, in request
    return session.request(method=method, url=url, **kwargs)
  File "/usr/local/lib/python3.7/site-packages/requests/sessions.py", line 519, in request
    prep = self.prepare_request(req)
  File "/usr/local/lib/python3.7/site-packages/requests/sessions.py", line 462, in prepare_request
    hooks=merge_hooks(request.hooks, self.hooks),
  File "/usr/local/lib/python3.7/site-packages/requests/models.py", line 313, in prepare
    self.prepare_url(url, params)
  File "/usr/local/lib/python3.7/site-packages/requests/models.py", line 387, in prepare_url
    raise MissingSchema(error)
requests.exceptions.MissingSchema: Invalid URL '//img21.mtime.cn/pi/2012/02/28/140754.27326186_1000X1000.jpg': No schema supplied. Perhaps you meant http:////img21.mtime.cn/pi/2012/02/28/140754.27326186_1000X1000.jpg?

[2019-12-28 14:31:38] name:黑镜.Black.Mirror.S01E03.Chi_Eng.WEB-HR.AAC.1024X576.x264-YYeTs人人影视.mkv url:https://91mjw.com/all/page/47 Invalid URL '//img31.mtime.cn/pi/2013/02/21/145802.88869224_1000X1000.jpg': No schema supplied. Perhaps you meant http:////img31.mtime.cn/pi/2013/02/21/145802.88869224_1000X1000.jpg?
Traceback (most recent call last):
  File "91.py", line 149, in <module>
    img_file = requests.get(img['data-original']).content
  File "/usr/local/lib/python3.7/site-packages/requests/api.py", line 75, in get
    return request('get', url, params=params, **kwargs)
  File "/usr/local/lib/python3.7/site-packages/requests/api.py", line 60, in request
    return session.request(method=method, url=url, **kwargs)
  File "/usr/local/lib/python3.7/site-packages/requests/sessions.py", line 519, in request
    prep = self.prepare_request(req)
  File "/usr/local/lib/python3.7/site-packages/requests/sessions.py", line 462, in prepare_request
    hooks=merge_hooks(request.hooks, self.hooks),
  File "/usr/local/lib/python3.7/site-packages/requests/models.py", line 313, in prepare
    self.prepare_url(url, params)
  File "/usr/local/lib/python3.7/site-packages/requests/models.py", line 387, in prepare_url
    raise MissingSchema(error)
requests.exceptions.MissingSchema: Invalid URL '//img31.mtime.cn/pi/2013/02/21/145802.88869224_1000X1000.jpg': No schema supplied. Perhaps you meant http:////img31.mtime.cn/pi/2013/02/21/145802.88869224_1000X1000.jpg?

[2019-12-28 14:33:53] name:打工姐妹花.2.Broke.Girls.S01E23-24.Chi_Eng.HR-HDTV.AC3.1024X576.x264-YYeTs人人影视.mkv url:https://91mjw.com/all/page/48 Invalid URL '//img21.mtime.cn/pi/2011/09/21/113233.29053513_1000X1000.jpg': No schema supplied. Perhaps you meant http:////img21.mtime.cn/pi/2011/09/21/113233.29053513_1000X1000.jpg?
Traceback (most recent call last):
  File "91.py", line 149, in <module>
    img_file = requests.get(img['data-original']).content
  File "/usr/local/lib/python3.7/site-packages/requests/api.py", line 75, in get
    return request('get', url, params=params, **kwargs)
  File "/usr/local/lib/python3.7/site-packages/requests/api.py", line 60, in request
    return session.request(method=method, url=url, **kwargs)
  File "/usr/local/lib/python3.7/site-packages/requests/sessions.py", line 519, in request
    prep = self.prepare_request(req)
  File "/usr/local/lib/python3.7/site-packages/requests/sessions.py", line 462, in prepare_request
    hooks=merge_hooks(request.hooks, self.hooks),
  File "/usr/local/lib/python3.7/site-packages/requests/models.py", line 313, in prepare
    self.prepare_url(url, params)
  File "/usr/local/lib/python3.7/site-packages/requests/models.py", line 387, in prepare_url
    raise MissingSchema(error)
requests.exceptions.MissingSchema: Invalid URL '//img21.mtime.cn/pi/2011/09/21/113233.29053513_1000X1000.jpg': No schema supplied. Perhaps you meant http:////img21.mtime.cn/pi/2011/09/21/113233.29053513_1000X1000.jpg?

[2019-12-28 14:34:54] name:X战警：第一战 url:https://91mjw.com/all/page/48 Invalid URL '//img5.mtime.cn/mg/2016/12/29/145115.78094558_270X405X4.jpg': No schema supplied. Perhaps you meant http:////img5.mtime.cn/mg/2016/12/29/145115.78094558_270X405X4.jpg?
Traceback (most recent call last):
  File "91.py", line 100, in <module>
    img_file = requests.get(cover_picture_origin).content
  File "/usr/local/lib/python3.7/site-packages/requests/api.py", line 75, in get
    return request('get', url, params=params, **kwargs)
  File "/usr/local/lib/python3.7/site-packages/requests/api.py", line 60, in request
    return session.request(method=method, url=url, **kwargs)
  File "/usr/local/lib/python3.7/site-packages/requests/sessions.py", line 519, in request
    prep = self.prepare_request(req)
  File "/usr/local/lib/python3.7/site-packages/requests/sessions.py", line 462, in prepare_request
    hooks=merge_hooks(request.hooks, self.hooks),
  File "/usr/local/lib/python3.7/site-packages/requests/models.py", line 313, in prepare
    self.prepare_url(url, params)
  File "/usr/local/lib/python3.7/site-packages/requests/models.py", line 387, in prepare_url
    raise MissingSchema(error)
requests.exceptions.MissingSchema: Invalid URL '//img5.mtime.cn/mg/2016/12/29/145115.78094558_270X405X4.jpg': No schema supplied. Perhaps you meant http:////img5.mtime.cn/mg/2016/12/29/145115.78094558_270X405X4.jpg?

[2019-12-28 14:35:45] name:行尸走肉.The.Walking.Dead.S01E06.中英字幕.BDrip.1080P-人人影视.mp4 url:https://91mjw.com/all/page/49 Invalid URL '//img21.mtime.cn/pi/2010/08/19/170358.98205051_1000X1000.jpg': No schema supplied. Perhaps you meant http:////img21.mtime.cn/pi/2010/08/19/170358.98205051_1000X1000.jpg?
Traceback (most recent call last):
  File "91.py", line 149, in <module>
    img_file = requests.get(img['data-original']).content
  File "/usr/local/lib/python3.7/site-packages/requests/api.py", line 75, in get
    return request('get', url, params=params, **kwargs)
  File "/usr/local/lib/python3.7/site-packages/requests/api.py", line 60, in request
    return session.request(method=method, url=url, **kwargs)
  File "/usr/local/lib/python3.7/site-packages/requests/sessions.py", line 519, in request
    prep = self.prepare_request(req)
  File "/usr/local/lib/python3.7/site-packages/requests/sessions.py", line 462, in prepare_request
    hooks=merge_hooks(request.hooks, self.hooks),
  File "/usr/local/lib/python3.7/site-packages/requests/models.py", line 313, in prepare
    self.prepare_url(url, params)
  File "/usr/local/lib/python3.7/site-packages/requests/models.py", line 387, in prepare_url
    raise MissingSchema(error)
requests.exceptions.MissingSchema: Invalid URL '//img21.mtime.cn/pi/2010/08/19/170358.98205051_1000X1000.jpg': No schema supplied. Perhaps you meant http:////img21.mtime.cn/pi/2010/08/19/170358.98205051_1000X1000.jpg?

[2019-12-28 14:41:33] name:终结者4 url:https://91mjw.com/all/page/51 Invalid URL '//img5.mtime.cn/mg/2016/12/30/161836.90482296_270X405X4.jpg': No schema supplied. Perhaps you meant http:////img5.mtime.cn/mg/2016/12/30/161836.90482296_270X405X4.jpg?
Traceback (most recent call last):
  File "91.py", line 100, in <module>
    img_file = requests.get(cover_picture_origin).content
  File "/usr/local/lib/python3.7/site-packages/requests/api.py", line 75, in get
    return request('get', url, params=params, **kwargs)
  File "/usr/local/lib/python3.7/site-packages/requests/api.py", line 60, in request
    return session.request(method=method, url=url, **kwargs)
  File "/usr/local/lib/python3.7/site-packages/requests/sessions.py", line 519, in request
    prep = self.prepare_request(req)
  File "/usr/local/lib/python3.7/site-packages/requests/sessions.py", line 462, in prepare_request
    hooks=merge_hooks(request.hooks, self.hooks),
  File "/usr/local/lib/python3.7/site-packages/requests/models.py", line 313, in prepare
    self.prepare_url(url, params)
  File "/usr/local/lib/python3.7/site-packages/requests/models.py", line 387, in prepare_url
    raise MissingSchema(error)
requests.exceptions.MissingSchema: Invalid URL '//img5.mtime.cn/mg/2016/12/30/161836.90482296_270X405X4.jpg': No schema supplied. Perhaps you meant http:////img5.mtime.cn/mg/2016/12/30/161836.90482296_270X405X4.jpg?

[2019-12-28 14:41:40] name:金刚狼 url:https://91mjw.com/all/page/51 Invalid URL '//img31.mtime.cn/mt/2014/02/23/035944.65256341_270X405.jpg': No schema supplied. Perhaps you meant http:////img31.mtime.cn/mt/2014/02/23/035944.65256341_270X405.jpg?
Traceback (most recent call last):
  File "91.py", line 100, in <module>
    img_file = requests.get(cover_picture_origin).content
  File "/usr/local/lib/python3.7/site-packages/requests/api.py", line 75, in get
    return request('get', url, params=params, **kwargs)
  File "/usr/local/lib/python3.7/site-packages/requests/api.py", line 60, in request
    return session.request(method=method, url=url, **kwargs)
  File "/usr/local/lib/python3.7/site-packages/requests/sessions.py", line 519, in request
    prep = self.prepare_request(req)
  File "/usr/local/lib/python3.7/site-packages/requests/sessions.py", line 462, in prepare_request
    hooks=merge_hooks(request.hooks, self.hooks),
  File "/usr/local/lib/python3.7/site-packages/requests/models.py", line 313, in prepare
    self.prepare_url(url, params)
  File "/usr/local/lib/python3.7/site-packages/requests/models.py", line 387, in prepare_url
    raise MissingSchema(error)
requests.exceptions.MissingSchema: Invalid URL '//img31.mtime.cn/mt/2014/02/23/035944.65256341_270X405.jpg': No schema supplied. Perhaps you meant http:////img31.mtime.cn/mt/2014/02/23/035944.65256341_270X405.jpg?

[2019-12-28 14:43:47] name:纳尼亚传奇2 url:https://91mjw.com/all/page/52 Invalid URL '//img31.mtime.cn/mt/2014/02/23/032907.78500360_270X405X4.jpg': No schema supplied. Perhaps you meant http:////img31.mtime.cn/mt/2014/02/23/032907.78500360_270X405X4.jpg?
Traceback (most recent call last):
  File "91.py", line 100, in <module>
    img_file = requests.get(cover_picture_origin).content
  File "/usr/local/lib/python3.7/site-packages/requests/api.py", line 75, in get
    return request('get', url, params=params, **kwargs)
  File "/usr/local/lib/python3.7/site-packages/requests/api.py", line 60, in request
    return session.request(method=method, url=url, **kwargs)
  File "/usr/local/lib/python3.7/site-packages/requests/sessions.py", line 519, in request
    prep = self.prepare_request(req)
  File "/usr/local/lib/python3.7/site-packages/requests/sessions.py", line 462, in prepare_request
    hooks=merge_hooks(request.hooks, self.hooks),
  File "/usr/local/lib/python3.7/site-packages/requests/models.py", line 313, in prepare
    self.prepare_url(url, params)
  File "/usr/local/lib/python3.7/site-packages/requests/models.py", line 387, in prepare_url
    raise MissingSchema(error)
requests.exceptions.MissingSchema: Invalid URL '//img31.mtime.cn/mt/2014/02/23/032907.78500360_270X405X4.jpg': No schema supplied. Perhaps you meant http:////img31.mtime.cn/mt/2014/02/23/032907.78500360_270X405X4.jpg?

[2019-12-28 14:46:27] name:X战警3 url:https://91mjw.com/all/page/54 Invalid URL '//img31.mtime.cn/mg/2014/10/20/100430.59203839_270X405X4.jpg': No schema supplied. Perhaps you meant http:////img31.mtime.cn/mg/2014/10/20/100430.59203839_270X405X4.jpg?
Traceback (most recent call last):
  File "91.py", line 100, in <module>
    img_file = requests.get(cover_picture_origin).content
  File "/usr/local/lib/python3.7/site-packages/requests/api.py", line 75, in get
    return request('get', url, params=params, **kwargs)
  File "/usr/local/lib/python3.7/site-packages/requests/api.py", line 60, in request
    return session.request(method=method, url=url, **kwargs)
  File "/usr/local/lib/python3.7/site-packages/requests/sessions.py", line 519, in request
    prep = self.prepare_request(req)
  File "/usr/local/lib/python3.7/site-packages/requests/sessions.py", line 462, in prepare_request
    hooks=merge_hooks(request.hooks, self.hooks),
  File "/usr/local/lib/python3.7/site-packages/requests/models.py", line 313, in prepare
    self.prepare_url(url, params)
  File "/usr/local/lib/python3.7/site-packages/requests/models.py", line 387, in prepare_url
    raise MissingSchema(error)
requests.exceptions.MissingSchema: Invalid URL '//img31.mtime.cn/mg/2014/10/20/100430.59203839_270X405X4.jpg': No schema supplied. Perhaps you meant http:////img31.mtime.cn/mg/2014/10/20/100430.59203839_270X405X4.jpg?

[2019-12-28 14:48:19] name:超人总动员 url:https://91mjw.com/all/page/55 Invalid URL '//img31.mtime.cn/mg/2014/04/28/183020.32371006_270X405X4.jpg': No schema supplied. Perhaps you meant http:////img31.mtime.cn/mg/2014/04/28/183020.32371006_270X405X4.jpg?
Traceback (most recent call last):
  File "91.py", line 100, in <module>
    img_file = requests.get(cover_picture_origin).content
  File "/usr/local/lib/python3.7/site-packages/requests/api.py", line 75, in get
    return request('get', url, params=params, **kwargs)
  File "/usr/local/lib/python3.7/site-packages/requests/api.py", line 60, in request
    return session.request(method=method, url=url, **kwargs)
  File "/usr/local/lib/python3.7/site-packages/requests/sessions.py", line 519, in request
    prep = self.prepare_request(req)
  File "/usr/local/lib/python3.7/site-packages/requests/sessions.py", line 462, in prepare_request
    hooks=merge_hooks(request.hooks, self.hooks),
  File "/usr/local/lib/python3.7/site-packages/requests/models.py", line 313, in prepare
    self.prepare_url(url, params)
  File "/usr/local/lib/python3.7/site-packages/requests/models.py", line 387, in prepare_url
    raise MissingSchema(error)
requests.exceptions.MissingSchema: Invalid URL '//img31.mtime.cn/mg/2014/04/28/183020.32371006_270X405X4.jpg': No schema supplied. Perhaps you meant http:////img31.mtime.cn/mg/2014/04/28/183020.32371006_270X405X4.jpg?

[2019-12-28 14:49:12] name:X战警2 url:https://91mjw.com/all/page/55 Invalid URL '//img5.mtime.cn/mg/2016/12/29/144815.98339503_270X405X4.jpg': No schema supplied. Perhaps you meant http:////img5.mtime.cn/mg/2016/12/29/144815.98339503_270X405X4.jpg?
Traceback (most recent call last):
  File "91.py", line 100, in <module>
    img_file = requests.get(cover_picture_origin).content
  File "/usr/local/lib/python3.7/site-packages/requests/api.py", line 75, in get
    return request('get', url, params=params, **kwargs)
  File "/usr/local/lib/python3.7/site-packages/requests/api.py", line 60, in request
    return session.request(method=method, url=url, **kwargs)
  File "/usr/local/lib/python3.7/site-packages/requests/sessions.py", line 519, in request
    prep = self.prepare_request(req)
  File "/usr/local/lib/python3.7/site-packages/requests/sessions.py", line 462, in prepare_request
    hooks=merge_hooks(request.hooks, self.hooks),
  File "/usr/local/lib/python3.7/site-packages/requests/models.py", line 313, in prepare
    self.prepare_url(url, params)
  File "/usr/local/lib/python3.7/site-packages/requests/models.py", line 387, in prepare_url
    raise MissingSchema(error)
requests.exceptions.MissingSchema: Invalid URL '//img5.mtime.cn/mg/2016/12/29/144815.98339503_270X405X4.jpg': No schema supplied. Perhaps you meant http:////img5.mtime.cn/mg/2016/12/29/144815.98339503_270X405X4.jpg?

[2019-12-28 14:49:26] name:终结者3 url:https://91mjw.com/all/page/55 Invalid URL '//img5.mtime.cn/mg/2016/12/30/161428.32016862_270X405X4.jpg': No schema supplied. Perhaps you meant http:////img5.mtime.cn/mg/2016/12/30/161428.32016862_270X405X4.jpg?
Traceback (most recent call last):
  File "91.py", line 100, in <module>
    img_file = requests.get(cover_picture_origin).content
  File "/usr/local/lib/python3.7/site-packages/requests/api.py", line 75, in get
    return request('get', url, params=params, **kwargs)
  File "/usr/local/lib/python3.7/site-packages/requests/api.py", line 60, in request
    return session.request(method=method, url=url, **kwargs)
  File "/usr/local/lib/python3.7/site-packages/requests/sessions.py", line 519, in request
    prep = self.prepare_request(req)
  File "/usr/local/lib/python3.7/site-packages/requests/sessions.py", line 462, in prepare_request
    hooks=merge_hooks(request.hooks, self.hooks),
  File "/usr/local/lib/python3.7/site-packages/requests/models.py", line 313, in prepare
    self.prepare_url(url, params)
  File "/usr/local/lib/python3.7/site-packages/requests/models.py", line 387, in prepare_url
    raise MissingSchema(error)
requests.exceptions.MissingSchema: Invalid URL '//img5.mtime.cn/mg/2016/12/30/161428.32016862_270X405X4.jpg': No schema supplied. Perhaps you meant http:////img5.mtime.cn/mg/2016/12/30/161428.32016862_270X405X4.jpg?

[2019-12-28 14:50:53] name:X战警 url:https://91mjw.com/all/page/56 Invalid URL '//img5.mtime.cn/mg/2016/12/29/144729.90533191_270X405X4.jpg': No schema supplied. Perhaps you meant http:////img5.mtime.cn/mg/2016/12/29/144729.90533191_270X405X4.jpg?
Traceback (most recent call last):
  File "91.py", line 100, in <module>
    img_file = requests.get(cover_picture_origin).content
  File "/usr/local/lib/python3.7/site-packages/requests/api.py", line 75, in get
    return request('get', url, params=params, **kwargs)
  File "/usr/local/lib/python3.7/site-packages/requests/api.py", line 60, in request
    return session.request(method=method, url=url, **kwargs)
  File "/usr/local/lib/python3.7/site-packages/requests/sessions.py", line 519, in request
    prep = self.prepare_request(req)
  File "/usr/local/lib/python3.7/site-packages/requests/sessions.py", line 462, in prepare_request
    hooks=merge_hooks(request.hooks, self.hooks),
  File "/usr/local/lib/python3.7/site-packages/requests/models.py", line 313, in prepare
    self.prepare_url(url, params)
  File "/usr/local/lib/python3.7/site-packages/requests/models.py", line 387, in prepare_url
    raise MissingSchema(error)
requests.exceptions.MissingSchema: Invalid URL '//img5.mtime.cn/mg/2016/12/29/144729.90533191_270X405X4.jpg': No schema supplied. Perhaps you meant http:////img5.mtime.cn/mg/2016/12/29/144729.90533191_270X405X4.jpg?

[2019-12-28 14:52:04] name:终结者2 url:https://91mjw.com/all/page/57 Invalid URL '//img5.mtime.cn/mg/2017/03/04/103631.30445944_270X405X4.jpg': No schema supplied. Perhaps you meant http:////img5.mtime.cn/mg/2017/03/04/103631.30445944_270X405X4.jpg?
Traceback (most recent call last):
  File "91.py", line 100, in <module>
    img_file = requests.get(cover_picture_origin).content
  File "/usr/local/lib/python3.7/site-packages/requests/api.py", line 75, in get
    return request('get', url, params=params, **kwargs)
  File "/usr/local/lib/python3.7/site-packages/requests/api.py", line 60, in request
    return session.request(method=method, url=url, **kwargs)
  File "/usr/local/lib/python3.7/site-packages/requests/sessions.py", line 519, in request
    prep = self.prepare_request(req)
  File "/usr/local/lib/python3.7/site-packages/requests/sessions.py", line 462, in prepare_request
    hooks=merge_hooks(request.hooks, self.hooks),
  File "/usr/local/lib/python3.7/site-packages/requests/models.py", line 313, in prepare
    self.prepare_url(url, params)
  File "/usr/local/lib/python3.7/site-packages/requests/models.py", line 387, in prepare_url
    raise MissingSchema(error)
requests.exceptions.MissingSchema: Invalid URL '//img5.mtime.cn/mg/2017/03/04/103631.30445944_270X405X4.jpg': No schema supplied. Perhaps you meant http:////img5.mtime.cn/mg/2017/03/04/103631.30445944_270X405X4.jpg?

[2019-12-28 14:52:23] name:终结者 url:https://91mjw.com/all/page/58 Invalid URL '//img31.mtime.cn/mg/2015/08/26/000808.11769015_270X405X4.jpg': No schema supplied. Perhaps you meant http:////img31.mtime.cn/mg/2015/08/26/000808.11769015_270X405X4.jpg?
Traceback (most recent call last):
  File "91.py", line 100, in <module>
    img_file = requests.get(cover_picture_origin).content
  File "/usr/local/lib/python3.7/site-packages/requests/api.py", line 75, in get
    return request('get', url, params=params, **kwargs)
  File "/usr/local/lib/python3.7/site-packages/requests/api.py", line 60, in request
    return session.request(method=method, url=url, **kwargs)
  File "/usr/local/lib/python3.7/site-packages/requests/sessions.py", line 519, in request
    prep = self.prepare_request(req)
  File "/usr/local/lib/python3.7/site-packages/requests/sessions.py", line 462, in prepare_request
    hooks=merge_hooks(request.hooks, self.hooks),
  File "/usr/local/lib/python3.7/site-packages/requests/models.py", line 313, in prepare
    self.prepare_url(url, params)
  File "/usr/local/lib/python3.7/site-packages/requests/models.py", line 387, in prepare_url
    raise MissingSchema(error)
requests.exceptions.MissingSchema: Invalid URL '//img31.mtime.cn/mg/2015/08/26/000808.11769015_270X405X4.jpg': No schema supplied. Perhaps you meant http:////img31.mtime.cn/mg/2015/08/26/000808.11769015_270X405X4.jpg?

